Workbook

Sheet INDEX overview
A1: Model at a glance
A2: Item | B2: Summary
A3: Purpose of Index | B3: Compares jurisdiction readiness for credible coal-to-clean transition credit activity
A4: Country universe | B4: Jurisdictions with operating coal capacity recorded by GEM (eligibility gate) > with material transition opportunity (screening)
A5: Output | B5: Overall implementation readiness score, pillar scores and country ranking
A6: Scoring | B6: Indicators normalised to 0–100, weighted within pillars, then combined
A7: Data basis | B7: 2024 is the principal base year, with disclosed exceptions for dynamic trackers, multi-year windows and less frequently updated datasets
A8: Overlay | B8: Market-confidence evidence adjusts indicator weights, not country data
A9: Missing data | B9: Missing observations are estimated separately and clearly flagged
A12: Screening
A13: Stage | B13: Variable | C13: Rule or treatment | D13: Selected central threshold | E13: Current result | F13: Notes
A14: Eligibility gate | B14: Operating coal capacity | C14: Pass when operating coal capacity is greater than zero | D14: Greater than 0 MW | E14: 73 eligible jurisdictions | F14: No GEM country record is treated as zero recorded operating capacity
A15: Material-opportunity screen | B15: Operating coal capacity | C15: One of three opportunity conditions | D15: 1,907 MW | F15: Median threshold among eligible jurisdictions
A16: Material-opportunity screen | B16: Coal generation share | C16: One of three opportunity conditions | D16: 20.260% | F16: Threshold derived from reported Ember data; documented estimates may be used to screen a country
A17: Material-opportunity screen | B17: Estimated lifetime CO₂ | C17: One of three opportunity conditions | D17: 70.511 Mt | F17: Country-level source calculation from WIP.xlsx
A18: Material-opportunity screen | B18: Minimum conditions | C18: Meet at least two of the three opportunity conditions | D18: 2 of 3 | E18: 36 pass; 37 fail | F18: Central scenario selected for the base index
A20: Pillar overview
A21: Pillar | B21: Overall weight | C21: Key treatment
A22: Pillar 1: Energy system conditions | B22: 0.2 | C22: Operating coal capacity and coal share are screening variables. They remain visible for audit but have zero Pillar 1 weight
A23: Pillar 2: Policy and transition commitment | B23: 0.2 | C23: Combines policy infrastructure, transition direction and documented coal-phaseout implementation. Expansion and construction inputs are already ratios
A24: Pillar 3: Governance and institutional capacity | B24: 0.15 | C24: World Bank governance indicators are already converted to comparable 0–100 scores
A25: Pillar 4: Carbon market maturity | B25: 0.2 | C25: VCM indicators use logarithmic scaling. Article 6 indicators use institutional milestones and implementation-stage scores
A26: Pillar 5: Macro-financial conditions | B26: 0.15 | C26: Higher financial depth is favourable. High inflation, debt pressure and exchange-rate instability reduce readiness
A27: Pillar 6: Just transition and social credibility | B27: 0.1 | C27: The resilience indicator combines social-protection coverage and HDI. Unemployment represents labour-market absorption risk
A30: Indicator reference
A31: Pillar | B31: Indicator | C31: Weight | D31: Data year | E31: Metric and source | F31: Scoring
A32: Screening | B32: Operating coal capacity | C32: 0 | D32: January 2026 | E32: Operating coal capacity, MW – GEM Global Coal Plant Tracker | F32: Eligibility requires capacity above 0 MW. Central opportunity condition requires at least 1,907 MW.
A33: Screening | B33: Coal share of electricity generation | C33: 0 | D33: 2024 | E33: Coal generation share, % – Ember | F33: Central opportunity condition requires at least 20.260%. Not included in Pillar 1 scoring.
A34: Screening | B34: Estimated remaining lifetime CO₂ | C34: 0 | D34: January 2026 | E34: Estimated remaining lifetime emissions, MtCO₂ – calculated from GEM unit-level plant data | F34: Central opportunity condition requires at least 70.511 MtCO₂.
A35: 1. Energy system conditions | B35: Renewable electricity share | C35: 0.35 | D35: 2024 | E35: Renewable share of electricity generation, % – Ember | F35: Higher is better – min–max normalisation.
A36: 1. Energy system conditions | B36: Wind and solar share | C36: 0.3 | D36: 2024 | E36: Wind and solar share of electricity generation, % – Ember | F36: Higher is better – min–max normalisation.
A37: 1. Energy system conditions | B37: Grid emissions intensity | C37: 0.35 | D37: 2024 | E37: Grid emissions intensity, gCO₂e/kWh – Ember | F37: Lower is better – reverse P5/P95 winsorised score.
A38: 2. Policy and transition commitment | B38: Renewable energy policy and regulatory readiness | C38: 0.12 | D38: 2023 | E38: Renewable Energy score, 0–100 – World Bank RISE | F38: Direct 0–100 score.
A39: 2. Policy and transition commitment | B39: Coal expansion pressure | C39: 0.16 | D39: January 2026 | E39: Announced, pre-permit and permitted coal capacity divided by operating coal capacity – GEM | F39: Lower is better – reverse score using a P95 cap.
A40: 2. Policy and transition commitment | B40: Coal construction pressure | C40: 0.12 | D40: January 2026 | E40: Coal capacity under construction divided by operating coal capacity – GEM | F40: Lower is better – reverse score using a P95 cap.
A41: 2. Policy and transition commitment | B41: Coal share five-year trend | C41: 0.12 | D41: 2019–2024 | E41: Linear trend in coal generation share, percentage points per year – Ember | F41: Lower is better – reverse P5/P95 winsorised score.
A42: 2. Policy and transition commitment | B42: Renewables share five-year trend | C42: 0.12 | D42: 2019–2024 | E42: Linear trend in renewable generation share, percentage points per year – Ember | F42: Higher is better – P5/P95 winsorised score.
A43: 2. Policy and transition commitment | B43: Grid emissions intensity five-year trend | C43: 0.08 | D43: 2019–2024 | E43: Linear trend in grid emissions intensity, gCO₂/kWh per year – Ember | F43: Lower is better – reverse P5/P95 winsorised score.
... A63: 6. Just transition and social credibility | B63: Coal transition social exposure proxy | C63: 0 | D63: January 2026 capacity; 2024 population | E63: Operating coal MW per million people – GEM and World Bank population | F63: Lower is better – reverse log1p scaling
A66: Dropped indicators
...

Sheet INDEX
A1: JURISDICTIONAL READINESS INDEX FOR COAL-TO -CLEAN TRANSITION OPPORTUNITIES | C1: Pillar weights
C2: 0.2 | D2: 0.2 | E2: 0.15 | F2: 0.2 | G2: 0.15 | H2: 0.1 | I2: =SUM(C2:H2) -> 1
A3: Country | B3: ISO3 | C3: PILLAR 1 SCORE Energy system conditions | D3: PILLAR 2 SCORE Policy and transition commitment | E3: PILLAR 3 SCORE Governance and institutional capacity | F3: PILLAR 4 SCORE Carbon market maturity | G3: PILLAR 5 SCORE Macro-financial conditions | H3: PILLAR 6 SCORE Just transition and social credibility | I3: Overall index score | J3: Rank | L3: Number of estimated indicator inputs | M3: Data-confidence level | O3: Provisional overlay-adjusted score | P3: Provisional overlay-adjusted rank
A4: {=_xlfn._xlws.FILTER(Screening!$A$2:$B$216,Screening!$L$2:$L$216="Yes","")} -> Australia | B4: AUS | C4: =IF($B4="","",_xlfn.XLOOKUP($B4,'Pillar-1'!$B$5:$B$216,'Pillar-1'!$M$5:$M$216,"",0)) -> 46.551741 | D4: =IF($B4="","",_xlfn.XLOOKUP($B4,'Pillar-2'!$B$5:$B$216,'Pillar-2'!$S$5:$S$216,"",0)) -> 69.782657 | E4: =IF($B4="","",_xlfn.XLOOKUP($B4,'Pillar-3'!$B$5:$B$217,'Pillar-3'!$M$5:$M$217,"",0)) -> 83.6035 | F4: =IF($B4="","",_xlfn.XLOOKUP($B4,'Pillar-4'!$B$5:$B$217,'Pillar-4'!$R$5:$R$217,"",0)) -> 38.13411 | G4: =IF($B4="","",_xlfn.XLOOKUP($B4,'Pillar-5'!$B$5:$B$216,'Pillar-5'!$O$5:$O$216,"",0)) -> 74.902856 | H4: =IF($B4="","",_xlfn.XLOOKUP($B4,'Pillar-6'!$B$5:$B$216,'Pillar-6'!$O$5:$O$216,"",0)) -> 83.5835 | I4: =IF(COUNT(C4:H4)=6,SUMPRODUCT(C4:H4,$C$2:$H$2),"") -> 63.028005 | J4: =IF(ISNUMBER(I4),1+COUNTIF($I$4:$I$39,">"&I4),"") -> 6 | L4: =IF($B4="","",SUM(_xlfn.XLOOKUP($B4,'Pillar-1'!$B$57:$B$92,'Pillar-1'!$F$57:$F$92,0,0),_xlfn.XLOOKUP($B4,'Pillar-2'!$B$65:$B$100,'Pillar-2'!$K$65:$K$100,0,0),_xlfn.XLOOKUP($B4,'Pillar-3'!$B$54:$B$89,'Pillar-3'!$H$54:$H$89,0,0),_xlfn.XLOOKUP($B4,'Pillar-4'!$B$65:$B$100,'Pillar-4'!$H$65:$H$100,0,0),_xlfn.XLOOKUP($B4,'Pillar-5'!$B$80:$B$115,'Pillar-5'!$G$80:$G$115,0,0),_xlfn.XLOOKUP($B4,'Pillar-6'!$B$74:$B$109,'Pillar-6'!$F$74:$F$109,0,0))) -> 0 | M4: =IF($B4="","",IF(L4<=1,"Higher",IF(L4<=3,"Moderate","Lower"))) -> Higher | O4: =IF(COUNT(C4:H4)=6,C4*#REF!+D4*#REF!+E4*#REF!+F4*#REF!+G4*#REF!+H4*#REF!,"") -> #REF! | P4: =IF(ISNUMBER(O4),1+COUNTIF($O$4:$O$39,">"&O4),"")
A5: Bangladesh | B5: BGD | C5: =IF($B5="","",_xlfn.XLOOKUP($B5,'Pillar-1'!$B$5:$B$216,'Pillar-1'!$M$5:$M$216,"",0)) -> 3.9510783 | D5: =IF($B5="","",_xlfn.XLOOKUP($B5,'Pillar-2'!$B$5:$B$216,'Pillar-2'!$S$5:$S$216,"",0)) -> 12.97493 | E5: =IF($B5="","",_xlfn.XLOOKUP($B5,'Pillar-3'!$B$5:$B$217,'Pillar-3'!$M$5:$M$217,"",0)) -> 37.0855 | F5: =IF($B5="","",_xlfn.XLOOKUP($B5,'Pillar-4'!$B$5:$B$217,'Pillar-4'!$R$5:$R$217,"",0)) -> 77.299124 | G5: =IF($B5="","",_xlfn.XLOOKUP($B5,'Pillar-5'!$B$5:$B$216,'Pillar-5'!$O$5:$O$216,"",0)) -> 46.704982 | H5: =IF($B5="","",_xlfn.XLOOKUP($B5,'Pillar-6'!$B$5:$B$216,'Pillar-6'!$O$5:$O$216,"",0)) -> 44.22375 | I5: =IF(COUNT(C5:H5)=6,SUMPRODUCT(C5:H5,$C$2:$H$2),"") -> 35.835974 | J5: =IF(ISNUMBER(I5),1+COUNTIF($I$4:$I$179,">"&I5),"") -> 36 | L5: =IF($B5="","",SUM(_xlfn.XLOOKUP($B5,'Pillar-1'!$B$57:$B$92,'Pillar-1'!$F$57:$F$92,0,0),_xlfn.XLOOKUP($B5,'Pillar-2'!$B$65:$B$100,'Pillar-2'!$K$65:$K$100,0,0),_xlfn.XLOOKUP($B5,'Pillar-3'!$B$54:$B$89,'Pillar-3'!$H$54:$H$89,0,0),_xlfn.XLOOKUP($B5,'Pillar-4'!$B$65:$B$100,'Pillar-4'!$H$65:$H$100,0,0),_xlfn.XLOOKUP($B5,'Pillar-5'!$B$80:$B$115,'Pillar-5'!$G$80:$G$115,0,0),_xlfn.XLOOKUP($B5,'Pillar-6'!$B$74:$B$109,'Pillar-6'!$F$74:$F$109,0,0))) -> 0 | M5: =IF($B5="","",IF(L5<=1,"Higher",IF(L5<=3,"Moderate","Lower"))) -> Higher | O5: =IF(COUNT(C5:H5)=6,C5*#REF!+D5*#REF!+E5*#REF!+F5*#REF!+G5*#REF!+H5*#REF!,"") -> #REF! | P5: =IF(ISNUMBER(O5),1+COUNTIF($O$4:$O$39,">"&O5),"")
A6: Bosnia and Herzegovina | B6: BIH | C6: =IF($B6="","",_xlfn.XLOOKUP($B6,'Pillar-1'!$B$5:$B$216,'Pillar-1'!$M$5:$M$216,"",0)) -> 28.514445 | D6: =IF($B6="","",_xlfn.XLOOKUP($B6,'Pillar-2'!$B$5:$B$216,'Pillar-2'!$S$5:$S$216,"",0)) -> 38.326415 | E6: =IF($B6="","",_xlfn.XLOOKUP($B6,'Pillar-3'!$B$5:$B$217,'Pillar-3'!$M$5:$M$217,"",0)) -> 45.607 | F6: =IF($B6="","",_xlfn.XLOOKUP($B6,'Pillar-4'!$B$5:$B$217,'Pillar-4'!$R$5:$R$217,"",0)) -> 0 | G6: =IF($B6="","",_xlfn.XLOOKUP($B6,'Pillar-5'!$B$5:$B$216,'Pillar-5'!$O$5:$O$216,"",0)) -> 66.484901 | H6: =IF($B6="","",_xlfn.XLOOKUP($B6,'Pillar-6'!$B$5:$B$216,'Pillar-6'!$O$5:$O$216,"",0)) -> 59.60425 | I6: =IF(COUNT(C6:H6)=6,SUMPRODUCT(C6:H6,$C$2:$H$2),"") -> 36.142382 | J6: =IF(ISNUMBER(I6),1+COUNTIF($I$4:$I$179,">"&I6),"") -> 35 | L6: =IF($B6="","",SUM(_xlfn.XLOOKUP($B6,'Pillar-1'!$B$57:$B$92,'Pillar-1'!$F$57:$F$92,0,0),_xlfn.XLOOKUP($B6,'Pillar-2'!$B$65:$B$100,'Pillar-2'!$K$65:$K$100,0,0),_xlfn.XLOOKUP($B6,'Pillar-3'!$B$54:$B$89,'Pillar-3'!$H$54:$H$89,0,0),_xlfn.XLOOKUP($B6,'Pillar-4'!$B$65:$B$100,'Pillar-4'!$H$65:$H$100,0,0),_xlfn.XLOOKUP($B6,'Pillar-5'!$B$80:$B$115,'Pillar-5'!$G$80:$G$115,0,0),_xlfn.XLOOKUP($B6,'Pillar-6'!$B$74:$B$109,'Pillar-6'!$F$74:$F$109,0,0))) -> 0 | M6: =IF($B6="","",IF(L6<=1,"Higher",IF(L6<=3,"Moderate","Lower"))) -> Higher | O6: =IF(COUNT(C6:H6)=6,C6*#REF!+D6*#REF!+E6*#REF!+F6*#REF!+G6*#REF!+H6*#REF!,"") -> #REF! | P6: =IF(ISNUMBER(O6),1+COUNTIF($O$4:$O$39,">"&O6),"")
A7: Brazil | B7: BRA | C7: =IF($B7="","",_xlfn.XLOOKUP($B7,'Pillar-1'!$B$5:$B$216,'Pillar-1'!$M$5:$M$216,"",0)) -> 86.575121 | D7: =IF($B7="","",_xlfn.XLOOKUP($B7,'Pillar-2'!$B$5:$B$216,'Pillar-2'!$S$5:$S$216,"",0)) -> 56.001412 | E7: =IF($B7="","",_xlfn.XLOOKUP($B7,'Pillar-3'!$B$5:$B$217,'Pillar-3'!$M$5:$M$217,"",0)) -> 47.772 | F7: =IF($B7="","",_xlfn.XLOOKUP($B7,'Pillar-4'!$B$5:$B$217,'Pillar-4'!$R$5:$R$217,"",0)) -> 72.481828 | G7: =IF($B7="","",_xlfn.XLOOKUP($B7,'Pillar-5'!$B$5:$B$216,'Pillar-5'!$O$5:$O$216,"",0)) -> 53.849575 | H7: =IF($B7="","",_xlfn.XLOOKUP($B7,'Pillar-6'!$B$5:$B$216,'Pillar-6'!$O$5:$O$216,"",0)) -> 63.9555 | I7: =IF(COUNT(C7:H7)=6,SUMPRODUCT(C7:H7,$C$2:$H$2),"") -> 64.650458 | J7: =IF(ISNUMBER(I7),1+COUNTIF($I$4:$I$179,">"&I7),"") -> 5 | L7: =IF($B7="","",SUM(_xlfn.XLOOKUP($B7,'Pillar-1'!$B$57:$B$92,'Pillar-1'!$F$57:$F$92,0,0),_xlfn.XLOOKUP($B7,'Pillar-2'!$B$65:$B$100,'Pillar-2'!$K$65:$K$100,0,0),_xlfn.XLOOKUP($B7,'Pillar-3'!$B$54:$B$89,'Pillar-3'!$H$54:$H$89,0,0),_xlfn.XLOOKUP($B7,'Pillar-4'!$B$65:$B$100,'Pillar-4'!$H$65:$H$100,0,0),_xlfn.XLOOKUP($B7,'Pillar-5'!$B$80:$B$115,'Pillar-5'!$G$80:$G$115,0,0),_xlfn.XLOOKUP($B7,'Pillar-6'!$B$74:$B$109,'Pillar-6'!$F$74:$F$109,0,0))) -> 0 | M7: =IF($B7="","",IF(L7<=1,"Higher",IF(L7<=3,"Moderate","Lower"))) -> Higher | O7: =IF(COUNT(C7:H7)=6,C7*#REF!+D7*#REF!+E7*#REF!+F7*#REF!+G7*#REF!+H7*#REF!,"") -> #REF! | P7: =IF(ISNUMBER(O7),1+COUNTIF($O$4:$O$39,">"&O7),"")
A8: Bulgaria | B8: BGR | C8: =IF($B8="","",_xlfn.XLOOKUP($B8,'Pillar-1'!$B$5:$B$216,'Pillar-1'!$M$5:$M$216,"",0)) -> 55.203175 | D8: =IF($B8="","",_xlfn.XLOOKUP($B8,'Pillar-2'!$B$5:$B$216,'Pillar-2'!$S$5:$S$216,"",0)) -> 69.049865 | E8: =IF($B8="","",_xlfn.XLOOKUP($B8,'Pillar-3'!$B$5:$B$217,'Pillar-3'!$M$5:$M$217,"",0)) -> 54.431 | F8: =IF($B8="","",_xlfn.XLOOKUP($B8,'Pillar-4'!$B$5:$B$217,'Pillar-4'!$R$5:$R$217,"",0)) -> 31.90232 | G8: =IF($B8="","",_xlfn.XLOOKUP($B8,'Pillar-5'!$B$5:$B$216,'Pillar-5'!$O$5:$O$216,"",0)) -> 67.029884 | H8: =IF($B8="","",_xlfn.XLOOKUP($B8,'Pillar-6'!$B$5:$B$216,'Pillar-6'!$O$5:$O$216,"",0)) -> 78.52775 | I8: =IF(COUNT(C8:H8)=6,SUMPRODUCT(C8:H8,$C$2:$H$2),"") -> 57.30298 | J8: =IF(ISNUMBER(I8),1+COUNTIF($I$4:$I$179,">"&I8),"") -> 11 | L8: =IF($B8="","",SUM(_xlfn.XLOOKUP($B8,'Pillar-1'!$B$57:$B$92,'Pillar-1'!$F$57:$F$92,0,0),_xlfn.XLOOKUP($B8,'Pillar-2'!$B$65:$B$100,'Pillar-2'!$K$65:$K$100,0,0),_xlfn.XLOOKUP($B8,'Pillar-3'!$B$54:$B$89,'Pillar-3'!$H$54:$H$89,0,0),_xlfn.XLOOKUP($B8,'Pillar-4'!$B$65:$B$100,'Pillar-4'!$H$65:$H$100,0,0),_xlfn.XLOOKUP($B8,'Pillar-5'!$B$80:$B$115,'Pillar-5'!$G$80:$G$115,0,0),_xlfn.XLOOKUP($B8,'Pillar-6'!$B$74:$B$109,'Pillar-6'!$F$74:$F$109,0,0))) -> 0 | M8: =IF($B8="","",IF(L8<=1,"Higher",IF(L8<=3,"Moderate","Lower"))) -> Higher | O8: =IF(COUNT(C8:H8)=6,C8*#REF!+D8*#REF!+E8*#REF!+F8*#REF!+G8*#REF!+H8*#REF!,"") -> #REF! | P8: =IF(ISNUMBER(O8),1+COUNTIF($O$4:$O$39,">"&O8),"")
A9: Cambodia | B9: KHM | C9: =IF($B9="","",_xlfn.XLOOKUP($B9,'Pillar-1'!$B$5:$B$216,'Pillar-1'!$M$5:$M$216,"",0)) -> 32.203217 | D9: =IF($B9="","",_xlfn.XLOOKUP($B9,'Pillar-2'!$B$5:$B$216,'Pillar-2'!$S$5:$S$216,"",0)) -> 17.988229 | E9: =IF($B9="","",_xlfn.XLOOKUP($B9,'Pillar-3'!$B$5:$B$217,'Pillar-3'!$M$5:$M$217,"",0)) -> 41.782 | F9: =IF($B9="","",_xlfn.XLOOKUP($B9,'Pillar-4'!$B$5:$B$217,'Pillar-4'!$R$5:$R$217,"",0)) -> 78.86397 | G9: =IF($B9="","",_xlfn.XLOOKUP($B9,'Pillar-5'!$B$5:$B$216,'Pillar-5'!$O$5:$O$216,"",0)) -> 84.482081 | H9: =IF($B9="","",_xlfn.XLOOKUP($B9,'Pillar-6'!$B$5:$B$216,'Pillar-6'!$O$5:$O$216,"",0)) -> 42.6285 | I9: =IF(COUNT(C9:H9)=6,SUMPRODUCT(C9:H9,$C$2:$H$2),"") -> 49.013545 | J9: =IF(ISNUMBER(I9),1+COUNTIF($I$4:$I$179,">"&I9),"") -> 20 | L9: =IF($B9="","",SUM(_xlfn.XLOOKUP($B9,'Pillar-1'!$B$57:$B$92,'Pillar-1'!$F$57:$F$92,0,0),_xlfn.XLOOKUP($B9,'Pillar-2'!$B$65:$B$100,'Pillar-2'!$K$65:$K$100,0,0),_xlfn.XLOOKUP($B9,'Pillar-3'!$B$54:$B$89,'Pillar-3'!$H$54:$H$89,0,0),_xlfn.XLOOKUP($B9,'Pillar-4'!$B$65:$B$100,'Pillar-4'!$H$65:$H$100,0,0),_xlfn.XLOOKUP($B9,'Pillar-5'!$B$80:$B$115,'Pillar-5'!$G$80:$G$115,0,0),_xlfn.XLOOKUP($B9,'Pillar-6'!$B$74:$B$109,'Pillar-6'!$F$74:$F$109,0,0))) -> 0 | M9: =IF($B9="","",IF(L9<=1,"Higher",IF(L9<=3,"Moderate","Lower"))) -> Higher | O9: =IF(COUNT(C9:H9)=6,C9*#REF!+D9*#REF!+E9*#REF!+F9*#REF!+G9*#REF!+H9*#REF!,"") -> #REF! | P9: =IF(ISNUMBER(O9),1+COUNTIF($O$4:$O$39,">"&O9),"")
A10: Canada | B10: CAN | C10: =IF($B10="","",_xlfn.XLOOKUP($B10,'Pillar-1'!$B$5:$B$216,'Pillar-1'!$M$5:$M$216,"",0)) -> 66.642502 | D10: =IF($B10="","",_xlfn.XLOOKUP($B10,'Pillar-2'!$B$5:$B$216,'Pillar-2'!$S$5:$S$216,"",0)) -> 61.782231 | E10: =IF($B10="","",_xlfn.XLOOKUP($B10,'Pillar-3'!$B$5:$B$217,'Pillar-3'!$M$5:$M$217,"",0)) -> 80.6845 | F10: =IF($B10="","",_xlfn.XLOOKUP($B10,'Pillar-4'!$B$5:$B$217,'Pillar-4'!$R$5:$R$217,"",0)) -> 45.087058 | G10: =IF($B10="","",_xlfn.XLOOKUP($B10,'Pillar-5'!$B$5:$B$216,'Pillar-5'!$O$5:$O$216,"",0)) -> 79.666175 | H10: =IF($B10="","",_xlfn.XLOOKUP($B10,'Pillar-6'!$B$5:$B$216,'Pillar-6'!$O$5:$O$216,"",0)) -> 78.75225 | I10: =IF(COUNT(C10:H10)=6,SUMPRODUCT(C10:H10,$C$2:$H$2),"") -> 66.630184 | J10: =IF(ISNUMBER(I10),1+COUNTIF($I$4:$I$179,">"&I10),"") -> 3 | L10: =IF($B10="","",SUM(_xlfn.XLOOKUP($B10,'Pillar-1'!$B$57:$B$92,'Pillar-1'!$F$57:$F$92,0,0),_xlfn.XLOOKUP($B10,'Pillar-2'!$B$65:$B$100,'Pillar-2'!$K$65:$K$100,0,0),_xlfn.XLOOKUP($B10,'Pillar-3'!$B$54:$B$89,'Pillar-3'!$H$54:$H$89,0,0),_xlfn.XLOOKUP($B10,'Pillar-4'!$B$65:$B$100,'Pillar-4'!$H$65:$H$100,0,0),_xlfn.XLOOKUP($B10,'Pillar-5'!$B$80:$B$115,'Pillar-5'!$G$80:$G$115,0,0),_xlfn.XLOOKUP($B10,'Pillar-6'!$B$74:$B$109,'Pillar-6'!$F$74:$F$109,0,0))) -> 1 | M10: =IF($B10="","",IF(L10<=1,"Higher",IF(L10<=3,"Moderate","Lower"))) -> Higher | O10: =IF(COUNT(C10:H10)=6,C10*#REF!+D10*#REF!+E10*#REF!+F10*#REF!+G10*#REF!+H10*#REF!,"") -> #REF! | P10: =IF(ISNUMBER(O10),1+COUNTIF($O$4:$O$39,">"&O10),"")
A11: Chile | B11: CHL | C11: =IF($B11="","",_xlfn.XLOOKUP($B11,'Pillar-1'!$B$5:$B$216,'Pillar-1'!$M$5:$M$216,"",0)) -> 84.124011 | D11: =IF($B11="","",_xlfn.XLOOKUP($B11,'Pillar-2'!$B$5:$B$216,'Pillar-2'!$S$5:$S$216,"",0)) -> 96.046667 | E11: =IF($B11="","",_xlfn.XLOOKUP($B11,'Pillar-3'!$B$5:$B$217,'Pillar-3'!$M$5:$M$217,"",0)) -> 68.9345 | F11: =IF($B11="","",_xlfn.XLOOKUP($B11,'Pillar-4'!$B$5:$B$217,'Pillar-4'!$R$5:$R$217,"",0)) -> 66.186105 | G11: =IF($B11="","",_xlfn.XLOOKUP($B11,'Pillar-5'!$B$5:$B$216,'Pillar-5'!$O$5:$O$216,"",0)) -> 64.399427 | H11: =IF($B11="","",_xlfn.XLOOKUP($B11,'Pillar-6'!$B$5:$B$216,'Pillar-6'!$O$5:$O$216,"",0)) -> 71.85375 | I11: =IF(COUNT(C11:H11)=6,SUMPRODUCT(C11:H11,$C$2:$H$2),"") -> 76.456821 | J11: =IF(ISNUMBER(I11),1+COUNTIF($I$4:$I$179,">"&I11),"") -> 1 | L11: =IF($B11="","",SUM(_xlfn.XLOOKUP($B11,'Pillar-1'!$B$57:$B$92,'Pillar-1'!$F$57:$F$92,0,0),_xlfn.XLOOKUP($B11,'Pillar-2'!$B$65:$B$100,'Pillar-2'!$K$65:$K$100,0,0),_xlfn.XLOOKUP($B11,'Pillar-3'!$B$54:$B$89,'Pillar-3'!$H$54:$H$89,0,0),_xlfn.XLOOKUP($B11,'Pillar-4'!$B$65:$B$100,'Pillar-4'!$H$65:$H$100,0,0),_xlfn.XLOOKUP($B11,'Pillar-5'!$B$80:$B$115,'Pillar-5'!$G$80:$G$115,0,0),_xlfn.XLOOKUP($B11,'Pillar-6'!$B$74:$B$109,'Pillar-6'!$F$74:$F$109,0,0))) -> 0 | M11: =IF($B11="","",IF(L11<=1,"Higher",IF(L11<=3,"Moderate","Lower"))) -> Higher | O11: =IF(COUNT(C11:H11)=6,C11*#REF!+D11*#REF!+E11*#REF!+F11*#REF!+G11*#REF!+H11*#REF!,"") -> #REF! | P11: =IF(ISNUMBER(O11),1+COUNTIF($O$4:$O$39,">"&O11),"")
A12: China | B12: CHN | C12: =IF($B12="","",_xlfn.XLOOKUP($B12,'Pillar-1'!$B$5:$B$216,'Pillar-1'!$M$5:$M$216,"",0)) -> 38.100942 | D12: =IF($B12="","",_xlfn.XLOOKUP($B12,'Pillar-2'!$B$5:$B$216,'Pillar-2'!$S$5:$S$216,"",0)) -> 43.783305 | E12: =IF($B12="","",_xlfn.XLOOKUP($B12,'Pillar-3'!$B$5:$B$217,'Pillar-3'!$M$5:$M$217,"",0)) -> 56.281 | F12: =IF($B12="","",_xlfn.XLOOKUP($B12,'Pillar-4'!$B$5:$B$217,'Pillar-4'!$R$5:$R$217,"",0)) -> 63.496375 | G12: =IF($B12="","",_xlfn.XLOOKUP($B12,'Pillar-5'!$B$5:$B$216,'Pillar-5'!$O$5:$O$216,"",0)) -> 80.979037 | H12: =IF($B12="","",_xlfn.XLOOKUP($B12,'Pillar-6'!$B$5:$B$216,'Pillar-6'!$O$5:$O$216,"",0)) -> 64.15425 | I12: =IF(COUNT(C12:H12)=6,SUMPRODUCT(C12:H12,$C$2:$H$2),"") -> 56.080555 | J12: =IF(ISNUMBER(I12),1+COUNTIF($I$4:$I$179,">"&I12),"") -> 13 | L12: =IF($B12="","",SUM(_xlfn.XLOOKUP($B12,'Pillar-1'!$B$57:$B$92,'Pillar-1'!$F$57:$F$92,0,0),_xlfn.XLOOKUP($B12,'Pillar-2'!$B$65:$B$100,'Pillar-2'!$K$65:$K$100,0,0),_xlfn.XLOOKUP($B12,'Pillar-3'!$B$54:$B$89,'Pillar-3'!$H$54:$H$89,0,0),_xlfn.XLOOKUP($B12,'Pillar-4'!$B$65:$B$100,'Pillar-4'!$H$65:$H$100,0,0),_xlfn.XLOOKUP($B12,'Pillar-5'!$B$80:$B$115,'Pillar-5'!$G$80:$G$115,0,0),_xlfn.XLOOKUP($B12,'Pillar-6'!$B$74:$B$109,'Pillar-6'!$F$74:$F$109,0,0))) -> 0 | M12: =IF($B12="","",IF(L12<=1,"Higher",IF(L12<=3,"Moderate","Lower"))) -> Higher | O12: =IF(COUNT(C12:H12)=6,C12*#REF!+D12*#REF!+E12*#REF!+F12*#REF!+G12*#REF!+H12*#REF!,"") -> #REF! | P12: =IF(ISNUMBER(O12),1+COUNTIF($O$4:$O$39,">"&O12),"")
A13: Czech Republic | B13: CZE | C13: =IF($B13="","",_xlfn.XLOOKUP($B13,'Pillar-1'!$B$5:$B$216,'Pillar-1'!$M$5:$M$216,"",0)) -> 32.268071 | D13: =IF($B13="","",_xlfn.XLOOKUP($B13,'Pillar-2'!$B$5:$B$216,'Pillar-2'!$S$5:$S$216,"",0)) -> 74.69426 | E13: =IF($B13="","",_xlfn.XLOOKUP($B13,'Pillar-3'!$B$5:$B$217,'Pillar-3'!$M$5:$M$217,"",0)) -> 74.202 | F13: =IF($B13="","",_xlfn.XLOOKUP($B13,'Pillar-4'!$B$5:$B$217,'Pillar-4'!$R$5:$R$217,"",0)) -> 4 | G13: =IF($B13="","",_xlfn.XLOOKUP($B13,'Pillar-5'!$B$5:$B$216,'Pillar-5'!$O$5:$O$216,"",0)) -> 62.885372 | H13: =IF($B13="","",_xlfn.XLOOKUP($B13,'Pillar-6'!$B$5:$B$216,'Pillar-6'!$O$5:$O$216,"",0)) -> 85.4895 | I13: =IF(COUNT(C13:H13)=6,SUMPRODUCT(C13:H13,$C$2:$H$2),"") -> 51.304522 | J13: =IF(ISNUMBER(I13),1+COUNTIF($I$4:$I$179,">"&I13),"") -> 19 | L13: =IF($B13="","",SUM(_xlfn.XLOOKUP($B13,'Pillar-1'!$B$57:$B$92,'Pillar-1'!$F$57:$F$92,0,0),_xlfn.XLOOKUP($B13,'Pillar-2'!$B$65:$B$100,'Pillar-2'!$K$65:$K$100,0,0),_xlfn.XLOOKUP($B13,'Pillar-3'!$B$54:$B$89,'Pillar-3'!$H$54:$H$89,0,0),_xlfn.XLOOKUP($B13,'Pillar-4'!$B$65:$B$100,'Pillar-4'!$H$65:$H$100,0,0),_xlfn.XLOOKUP($B13,'Pillar-5'!$B$80:$B$115,'Pillar-5'!$G$80:$G$115,0,0),_xlfn.XLOOKUP($B13,'Pillar-6'!$B$74:$B$109,'Pillar-6'!$F$74:$F$109,0,0))) -> 0 | M13: =IF($B13="","",IF(L13<=1,"Higher",IF(L13<=3,"Moderate","Lower"))) -> Higher | O13: =IF(COUNT(C13:H13)=6,C13*#REF!+D13*#REF!+E13*#REF!+F13*#REF!+G13*#REF!+H13*#REF!,"") -> #REF! | P13: =IF(ISNUMBER(O13),1+COUNTIF($O$4:$O$39,">"&O13),"")
A14: Dominican Republic | B14: DOM | C14: =IF($B14="","",_xlfn.XLOOKUP($B14,'Pillar-1'!$B$5:$B$216,'Pillar-1'!$M$5:$M$216,"",0)) -> 26.862616 | D14: =IF($B14="","",_xlfn.XLOOKUP($B14,'Pillar-2'!$B$5:$B$216,'Pillar-2'!$S$5:$S$216,"",0)) -> 39.015957 | E14: =IF($B14="","",_xlfn.XLOOKUP($B14,'Pillar-3'!$B$5:$B$217,'Pillar-3'!$M$5:$M$217,"",0)) -> 54.588 | F14: =IF($B14="","",_xlfn.XLOOKUP($B14,'Pillar-4'!$B$5:$B$217,'Pillar-4'!$R$5:$R$217,"",0)) -> 30.75 | G14: =IF($B14="","",_xlfn.XLOOKUP($B14,'Pillar-5'!$B$5:$B$216,'Pillar-5'!$O$5:$O$216,"",0)) -> 59.328467 | H14: =IF($B14="","",_xlfn.XLOOKUP($B14,'Pillar-6'!$B$5:$B$216,'Pillar-6'!$O$5:$O$216,"",0)) -> 73.0645 | I14: =IF(COUNT(C14:H14)=6,SUMPRODUCT(C14:H14,$C$2:$H$2),"") -> 43.719635 | J14: =IF(ISNUMBER(I14),1+COUNTIF($I$4:$I$179,">"&I14),"") -> 27 | L14: =IF($B14="","",SUM(_xlfn.XLOOKUP($B14,'Pillar-1'!$B$57:$B$92,'Pillar-1'!$F$57:$F$92,0,0),_xlfn.XLOOKUP($B14,'Pillar-2'!$B$65:$B$100,'Pillar-2'!$K$65:$K$100,0,0),_xlfn.XLOOKUP($B14,'Pillar-3'!$B$54:$B$89,'Pillar-3'!$H$54:$H$89,0,0),_xlfn.XLOOKUP($B14,'Pillar-4'!$B$65:$B$100,'Pillar-4'!$H$65:$H$100,0,0),_xlfn.XLOOKUP($B14,'Pillar-5'!$B$80:$B$115,'Pillar-5'!$G$80:$G$115,0,0),_xlfn.XLOOKUP($B14,'Pillar-6'!$B$74:$B$109,'Pillar-6'!$F$74:$F$109,0,0))) -> 0 | M14: =IF($B14="","",IF(L14<=1,"Higher",IF(L14<=3,"Moderate","Lower"))) -> Higher | O14: =IF(COUNT(C14:H14)=6,C14*#REF!+D14*#REF!+E14*#REF!+F14*#REF!+G14*#REF!+H14*#REF!,"") -> #REF! | P14: =IF(ISNUMBER(O14),1+COUNTIF($O$4:$O$39,">"&O14),"")
A15: Germany | B15: DEU | C15: =IF($B15="","",_xlfn.XLOOKUP($B15,'Pillar-1'!$B$5:$B$216,'Pillar-1'!$M$5:$M$216,"",0)) -> 80.528427 | D15: =IF($B15="","",_xlfn.XLOOKUP($B15,'Pillar-2'!$B$5:$B$216,'Pillar-2'!$S$5:$S$216,"",0)) -> 87.144209 | E15: =IF($B15="","",_xlfn.XLOOKUP($B15,'Pillar-3'!$B$5:$B$217,'Pillar-3'!$M$5:$M$217,"",0)) -> 80.517 | F15: =IF($B15="","",_xlfn.XLOOKUP($B15,'Pillar-4'!$B$5:$B$217,'Pillar-4'!$R$5:$R$217,"",0)) -> 49.027601 | G15: =IF($B15="","",_xlfn.XLOOKUP($B15,'Pillar-5'!$B$5:$B$216,'Pillar-5'!$O$5:$O$216,"",0)) -> 66.520655 | H15: =IF($B15="","",_xlfn.XLOOKUP($B15,'Pillar-6'!$B$5:$B$216,'Pillar-6'!$O$5:$O$216,"",0)) -> 99.35425 | I15: =IF(COUNT(C15:H15)=6,SUMPRODUCT(C15:H15,$C$2:$H$2),"") -> 75.33112 | J15: =IF(ISNUMBER(I15),1+COUNTIF($I$4:$I$179,">"&I15),"") -> 2 | L15: =IF($B15="","",SUM(_xlfn.XLOOKUP($B15,'Pillar-1'!$B$57:$B$92,'Pillar-1'!$F$57:$F$92,0,0),_xlfn.XLOOKUP($B15,'Pillar-2'!$B$65:$B$100,'Pillar-2'!$K$65:$K$100,0,0),_xlfn.XLOOKUP($B15,'Pillar-3'!$B$54:$B$89,'Pillar-3'!$H$54:$H$89,0,0),_xlfn.XLOOKUP($B15,'Pillar-4'!$B$65:$B$100,'Pillar-4'!$H$65:$H$100,0,0),_xlfn.XLOOKUP($B15,'Pillar-5'!$B$80:$B$115,'Pillar-5'!$G$80:$G$115,0,0),_xlfn.XLOOKUP($B15,'Pillar-6'!$B$74:$B$109,'Pillar-6'!$F$74:$F$109,0,0))) -> 1 | M15: =IF($B15="","",IF(L15<=1,"Higher",IF(L15<=3,"Moderate","Lower"))) -> Higher | O15: =IF(COUNT(C15:H15)=6,C15*#REF!+D15*#REF!+E15*#REF!+F15*#REF!+G15*#REF!+H15*#REF!,"") -> #REF! | P15: =IF(ISNUMBER(O15),1+COUNTIF($O$4:$O$39,">"&O15),"")
A16: Hong Kong | B16: HKG | C16: =IF($B16="","",_xlfn.XLOOKUP($B16,'Pillar-1'!$B$5:$B$216,'Pillar-1'!$M$5:$M$216,"",0)) -> 4.5636845 | D16: =IF($B16="","",_xlfn.XLOOKUP($B16,'Pillar-2'!$B$5:$B$216,'Pillar-2'!$S$5:$S$216,"",0)) -> 67.969412 | E16: =IF($B16="","",_xlfn.XLOOKUP($B16,'Pillar-3'!$B$5:$B$217,'Pillar-3'!$M$5:$M$217,"",0)) -> 79.537 | F16: =IF($B16="","",_xlfn.XLOOKUP($B16,'Pillar-4'!$B$5:$B$217,'Pillar-4'!$R$5:$R$217,"",0)) -> 1.8606328 | G16: =IF($B16="","",_xlfn.XLOOKUP($B16,'Pillar-5'!$B$5:$B$216,'Pillar-5'!$O$5:$O$216,"",0)) -> 97.983185 | H16: =IF($B16="","",_xlfn.XLOOKUP($B16,'Pillar-6'!$B$5:$B$216,'Pillar-6'!$O$5:$O$216,"",0)) -> 67.78125 | I16: =IF(COUNT(C16:H16)=6,SUMPRODUCT(C16:H16,$C$2:$H$2),"") -> 48.284899 | J16: =IF(ISNUMBER(I16),1+COUNTIF($I$4:$I$179,">"&I16),"") -> 21 | L16: =IF($B16="","",SUM(_xlfn.XLOOKUP($B16,'Pillar-1'!$B$57:$B$92,'Pillar-1'!$F$57:$F$92,0,0),_xlfn.XLOOKUP($B16,'Pillar-2'!$B$65:$B$100,'Pillar-2'!$K$65:$K$100,0,0),_xlfn.XLOOKUP($B16,'Pillar-3'!$B$54:$B$89,'Pillar-3'!$H$54:$H$89,0,0),_xlfn.XLOOKUP($B16,'Pillar-4'!$B$65:$B$100,'Pillar-4'!$H$65:$H$100,0,0),_xlfn.XLOOKUP($B16,'Pillar-5'!$B$80:$B$115,'Pillar-5'!$G$80:$G$115,0,0),_xlfn.XLOOKUP($B16,'Pillar-6'!$B$74:$B$109,'Pillar-6'!$F$74:$F$109,0,0))) -> 4 | M16: =IF($B16="","",IF(L16<=1,"Higher",IF(L16<=3,"Moderate","Lower"))) -> Lower | O16: =IF(COUNT(C16:H16)=6,C16*#REF!+D16*#REF!+E16*#REF!+F16*#REF!+G16*#REF!+H16*#REF!,"") -> #REF! | P16: =IF(ISNUMBER(O16),1+COUNTIF($O$4:$O$39,">"&O16),"")
... A39: Vietnam | B39: VNM | C39: =IF($B39="","",_xlfn.XLOOKUP($B39,'Pillar-1'!$B$5:$B$216,'Pillar-1'!$M$5:$M$216,"",0)) -> 42.588404 | D39: =IF($B39="","",_xlfn.XLOOKUP($B39,'Pillar-2'!$B$5:$B$216,'Pillar-2'!$S$5:$S$216,"",0)) -> 58.075052 | E39: =IF($B39="","",_xlfn.XLOOKUP($B39,'Pillar-3'!$B$5:$B$217,'Pillar-3'!$M$5:$M$217,"",0)) -> 50.513 | F39: =IF($B39="","",_xlfn.XLOOKUP($B39,'Pillar-4'!$B$5:$B$217,'Pillar-4'!$R$5:$R$217,"",0)) -> 70.649827 | G39: =IF($B39="","",_xlfn.XLOOKUP($B39,'Pillar-5'!$B$5:$B$216,'Pillar-5'!$O$5:$O$216,"",0)) -> 76.538933 | H39: =IF($B39="","",_xlfn.XLOOKUP($B39,'Pillar-6'!$B$5:$B$216,'Pillar-6'!$O$5:$O$216,"",0)) -> 57.26725 | I39: =IF(COUNT(C39:H39)=6,SUMPRODUCT(C39:H39,$C$2:$H$2),"") -> 59.047171 | J39: =IF(ISNUMBER(I39),1+COUNTIF($I$4:$I$179,">"&I39),"") -> 8 | L39: =IF($B39="","",SUM(_xlfn.XLOOKUP($B39,'Pillar-1'!$B$57:$B$92,'Pillar-1'!$F$57:$F$92,0,0),_xlfn.XLOOKUP($B39,'Pillar-2'!$B$65:$B$100,'Pillar-2'!$K$65:$K$100,0,0),_xlfn.XLOOKUP($B39,'Pillar-3'!$B$54:$B$89,'Pillar-3'!$H$54:$H$89,0,0),_xlfn.XLOOKUP($B39,'Pillar-4'!$B$65:$B$100,'Pillar-4'!$H$65:$H$100,0,0),_xlfn.XLOOKUP($B39,'Pillar-5'!$B$80:$B$115,'Pillar-5'!$G$80:$G$115,0,0),_xlfn.XLOOKUP($B39,'Pillar-6'!$B$74:$B$109,'Pillar-6'!$F$74:$F$109,0,0))) -> 1 | M39: =IF($B39="","",IF(L39<=1,"Higher",IF(L39<=3,"Moderate","Lower"))) -> Higher | O39: =IF(COUNT(C39:H39)=6,C39*#REF!+D39*#REF!+E39*#REF!+F39*#REF!+G39*#REF!+H39*#REF!,"") -> #REF! | P39: =IF(ISNUMBER(O39),1+COUNTIF($O$4:$O$39,">"&O39),"")
A42: Pillar score includes estimate(s)
A43: Index Score / Rank includes estimate(s)
A44: Overlay Adjusted Score / Rank includes estimate(s)

Sheet INDEX ranked
A1: JURISDICTIONAL READINESS INDEX FOR COAL-TO -CLEAN TRANSITION OPPORTUNITIES
A2: Country | B2: ISO3 | C2: Pillar 1 score Energy system conditions | D2: Pillar 2 score Policy and transition commitment | E2: Pillar 3 score Governance and institutional capacity | F2: Pillar 4 score Carbon market maturity | G2: Pillar 5 score Macro-financial conditions | H2: Pillar 6 score Just transition and social credibility | I2: Overall index score | J2: Rank
A3: {=_xlfn.LET( _xlpm.data,_xlfn._xlws.FILTER(_xlfn.HSTACK(INDEX!A4:J39,IF(INDEX!N4:N39="","",INDEX!N4:N39)),INDEX!A4:A39<>""), _xlpm.r,_xlfn._xlws.FILTER(INDEX!J4:J39,INDEX!A4:A39<>""), _xlfn.SORTBY(_xlpm.data,--(_xlpm.r=""),1,_xlpm.r,1) )} -> Chile | B3: CHL | C3: 84.124011 | D3: 96.046667 | E3: 68.9345 | F3: 66.186105 | G3: 64.399427 | H3: 71.85375 | I3: 76.456821 | J3: 1
A4: Germany | B4: DEU | C4: 80.528427 | D4: 87.144209 | E4: 80.517 | F4: 49.027601 | G4: 66.520655 | H4: 99.35425 | I4: 75.33112 | J4: 2
A5: Canada | B5: CAN | C5: 66.642502 | D5: 61.782231 | E5: 80.6845 | F5: 45.087058 | G5: 79.666175 | H5: 78.75225 | I5: 66.630184 | J5: 3
A6: United States | B6: USA | C6: 45.102471 | D6: 67.22198 | E6: 73.5955 | F6: 61.122227 | G6: 83.697333 | H6: 71.8225 | I6: 65.465511 | J6: 4
A7: Brazil | B7: BRA | C7: 86.575121 | D7: 56.001412 | E7: 47.772 | F7: 72.481828 | G7: 53.849575 | H7: 63.9555 | I7: 64.650458 | J7: 5
A8: Australia | B8: AUS | C8: 46.551741 | D8: 69.782657 | E8: 83.6035 | F8: 38.13411 | G8: 74.902856 | H8: 83.5835 | I8: 63.028005 | J8: 6
A9: South Korea | B9: KOR | C9: 29.213946 | D9: 75.030089 | E9: 73.707 | F9: 61.533748 | G9: 79.944199 | H9: 65.21625 | I9: 62.724861 | J9: 7
A10: Vietnam | B10: VNM | C10: 42.588404 | D10: 58.075052 | E10: 50.513 | F10: 70.649827 | G10: 76.538933 | H10: 57.26725 | I10: 59.047171 | J10: 8
A11: Sri Lanka | B11: LKA | C11: 55.031939 | D11: 79.768239 | E11: 48.546 | F11: 62.709379 | G11: 38.530653 | H11: 58.30225 | I11: 58.393634 | J11: 9
A12: Japan | B12: JPN | C12: 33.370858 | D12: 56.252323 | E12: 82.1295 | F12: 41.320255 | G12: 66.587888 | H12: 90.23925 | I12: 57.520221 | J12: 10
A13: Bulgaria | B13: BGR | C13: 55.203175 | D13: 69.049865 | E13: 54.431 | F13: 31.90232 | G13: 67.029884 | H13: 78.52775 | I13: 57.30298 | J13: 11
A14: Thailand | B14: THA | C14: 20.944702 | D14: 48.962463 | E14: 51.7125 | F14: 86.532861 | G14: 78.799662 | H14: 60.07275 | I14: 56.872104 | J14: 12
A15: China | B15: CHN | C15: 38.100942 | D15: 43.783305 | E15: 56.281 | F15: 63.496375 | G15: 80.979037 | H15: 64.15425 | I15: 56.080555 | J15: 13
... A38: Bangladesh | B38: BGD | C38: 3.9510783 | D38: 12.97493 | E38: 37.0855 | F38: 77.299124 | G38: 46.704982 | H38: 44.22375 | I38: 35.835974 | J38: 36

Sheet OVERLAY
A1: Final Q1 and Q2 market-salience overlay integration
A2: The analysis found more market-relevant factors than the index could directly score. Only constructs with a clear primary link to an existing indicator were applied to weights. Cross-cutting or project-specific factors were retained as contextual evidence to avoid forced mapping and double-counting.
A3: Pillar | D3: Indicator | F3: Primary mapped construct | G3: Base global weight | H3: Q1 multiplier | I3: Q1 adjusted weight | J3: Q2 multiplier | K3: Q2 adjusted weight
A4: PILLAR 1 – Energy system conditions | D4: P1 I1 – Renewable electricity share | F4: C01A | G4: =[2]INDEX!$C$2*'[2]Pillar-1'!$J$2 -> 0.07 | H4: 1 | I4: =G4*H4/SUMPRODUCT($G$4:$G$31,$H$4:$H$31) -> 0.067453626 | J4: 1 | K4: =G4*J4/SUMPRODUCT($G$4:$G$31,$J$4:$J$31) -> 0.068372729
A5: PILLAR 1 – Energy system conditions | D5: P1 I2 – Wind and solar share | F5: C01B | G5: =[2]INDEX!$C$2*'[2]Pillar-1'!$K$2 -> 0.06 | H5: 1 | I5: =G5*H5/SUMPRODUCT($G$4:$G$31,$H$4:$H$31) -> 0.057817393 | J5: 1 | K5: =G5*J5/SUMPRODUCT($G$4:$G$31,$J$4:$J$31) -> 0.058605196
A6: PILLAR 1 – Energy system conditions | D6: P1 I3 – Grid emissions intensity | F6: None | G6: =[2]INDEX!$C$2*'[2]Pillar-1'!$L$2 -> 0.07 | H6: 1 | I6: =G6*H6/SUMPRODUCT($G$4:$G$31,$H$4:$H$31) -> 0.067453626 | J6: 1 | K6: =G6*J6/SUMPRODUCT($G$4:$G$31,$J$4:$J$31) -> 0.068372729
A7: PILLAR 2 – Policy and transition commitment | D7: P2 I1 – Renewable energy policy and regulatory readiness | F7: C06 | G7: =[2]INDEX!$D$2*'[2]Pillar-2'!$K$2 -> 0.024 | H7: 1.1 | I7: =G7*H7/SUMPRODUCT($G$4:$G$31,$H$4:$H$31) -> 0.025439653 | J7: 1 | K7: =G7*J7/SUMPRODUCT($G$4:$G$31,$J$4:$J$31) -> 0.023442079
A8: PILLAR 2 – Policy and transition commitment | D8: P2 I2 – Coal expansion pressure | F8: C04A | G8: =[2]INDEX!$D$2*'[2]Pillar-2'!$L$2 -> 0.032 | H8: 1 | I8: =G8*H8/SUMPRODUCT($G$4:$G$31,$H$4:$H$31) -> 0.030835943 | J8: 1.05 | K8: =G8*J8/SUMPRODUCT($G$4:$G$31,$J$4:$J$31) -> 0.03281891
A9: PILLAR 2 – Policy and transition commitment | D9: P2 I3 – Coal construction pressure | F9: C04B | G9: =[2]INDEX!$D$2*'[2]Pillar-2'!$M$2 -> 0.024 | H9: 1 | I9: =G9*H9/SUMPRODUCT($G$4:$G$31,$H$4:$H$31) -> 0.023126957 | J9: 1.05 | K9: =G9*J9/SUMPRODUCT($G$4:$G$31,$J$4:$J$31) -> 0.024614182
A10: PILLAR 2 – Policy and transition commitment | D10: P2 I4 – Coal share 5yr linear trend slope | F10: C05A | G10: =[2]INDEX!$D$2*'[2]Pillar-2'!$N$2 -> 0.024 | H10: 1 | I10: =G10*H10/SUMPRODUCT($G$4:$G$31,$H$4:$H$31) -> 0.023126957 | J10: 1 | K10: =G10*J10/SUMPRODUCT($G$4:$G$31,$J$4:$J$31) -> 0.023442079
A11: PILLAR 2 – Policy and transition commitment | D11: P2 I5 – Renewables share 5y linear trend slope | F11: C05B | G11: =[2]INDEX!$D$2*'[2]Pillar-2'!$O$2 -> 0.024 | H11: 1 | I11: =G11*H11/SUMPRODUCT($G$4:$G$31,$H$4:$H$31) -> 0.023126957 | J11: 1 | K11: =G11*J11/SUMPRODUCT($G$4:$G$31,$J$4:$J$31) -> 0.023442079
A12: PILLAR 2 – Policy and transition commitment | D12: P2 I6 – Grid emissions intensity 5yr linear trend slope | F12: None | G12: =[2]INDEX!$D$2*'[2]Pillar-2'!$P$2 -> 0.016 | H12: 1 | I12: =G12*H12/SUMPRODUCT($G$4:$G$31,$H$4:$H$31) -> 0.015417972 | J12: 1 | K12: =G12*J12/SUMPRODUCT($G$4:$G$31,$J$4:$J$31) -> 0.015628052
A13: PILLAR 2 – Policy and transition commitment | D13: P2 I7 – Carbon-pricing infrastructure | F13: C07 | G13: =[2]INDEX!$D$2*'[2]Pillar-2'!$Q$2 -> 0.016 | H13: 1.1 | I13: =G13*H13/SUMPRODUCT($G$4:$G$31,$H$4:$H$31) -> 0.016959769 | J13: 1 | K13: =G13*J13/SUMPRODUCT($G$4:$G$31,$J$4:$J$31) -> 0.015628052
A14: PILLAR 2 – Policy and transition commitment | D14: P2 I8 – Coal phaseout commitment and documented implementation alignment | F14: C03 | G14: =[2]INDEX!$D$2*'[2]Pillar-2'!$R$2 -> 0.04 | H14: 1.2 | I14: =G14*H14/SUMPRODUCT($G$4:$G$31,$H$4:$H$31) -> 0.046253915 | J14: 1.2 | K14: =G14*J14/SUMPRODUCT($G$4:$G$31,$J$4:$J$31) -> 0.046884157
A15: PILLAR 3 – Governance and institutional capacity | D15: P3 I1 – Political stability | F15: C10A | G15: =[2]INDEX!$E$2*'[2]Pillar-3'!$H$2 -> 0.015 | H15: 1 | I15: =G15*H15/SUMPRODUCT($G$4:$G$31,$H$4:$H$31) -> 0.014454348 | J15: 1 | K15: =G15*J15/SUMPRODUCT($G$4:$G$31,$J$4:$J$31) -> 0.014651299
A16: PILLAR 3 – Governance and institutional capacity | D16: P3 I2 – Government effectiveness | F16: C08 | G16: =[2]INDEX!$E$2*'[2]Pillar-3'!$I$2 -> 0.0375 | H16: 1.05 | I16: =G16*H16/SUMPRODUCT($G$4:$G$31,$H$4:$H$31) -> 0.037942664 | J16: 1 | K16: =G16*J16/SUMPRODUCT($G$4:$G$31,$J$4:$J$31) -> 0.036628248
A17: PILLAR 3 – Governance and institutional capacity | D17: P3 I3 – Regulatory quality | F17: C09A | G17: =[2]INDEX!$E$2*'[2]Pillar-3'!$J$2 -> 0.0375 | H17: 1.05 | I17: =G17*H17/SUMPRODUCT($G$4:$G$31,$H$4:$H$31) -> 0.037942664 | J17: 1.1 | K17: =G17*J17/SUMPRODUCT($G$4:$G$31,$J$4:$J$31) -> 0.040291072
A18: PILLAR 3 – Governance and institutional capacity | D18: P3 I4 – Rule of law | F18: C09B | G18: =[2]INDEX!$E$2*'[2]Pillar-3'!$K$2 -> 0.03 | H18: 1.05 | I18: =G18*H18/SUMPRODUCT($G$4:$G$31,$H$4:$H$31) -> 0.030354132 | J18: 1.05 | K18: =G18*J18/SUMPRODUCT($G$4:$G$31,$J$4:$J$31) -> 0.030767728
A19: PILLAR 3 – Governance and institutional capacity | D19: P3 I5 – Control of corruption | F19: C10B | G19: =[2]INDEX!$E$2*'[2]Pillar-3'!$L$2 -> 0.03 | H19: 1 | I19: =G19*H19/SUMPRODUCT($G$4:$G$31,$H$4:$H$31) -> 0.028908697 | J19: 1 | K19: =G19*J19/SUMPRODUCT($G$4:$G$31,$J$4:$J$31) -> 0.029302598
A20: PILLAR 4 – Carbon market maturity | D20: P4 I1 – VCM project activity | F20: C12A | G20: =[2]INDEX!$F$2*'[2]Pillar-4'!$K$2 -> 0.04 | H20: 1 | I20: =G20*H20/SUMPRODUCT($G$4:$G$31,$H$4:$H$31) -> 0.038544929 | J20: 1 | K20: =G20*J20/SUMPRODUCT($G$4:$G$31,$J$4:$J$31) -> 0.039070131
A21: PILLAR 4 – Carbon market maturity | D21: P4 I2 – VCM issuance scale | F21: C12B | G21: =[2]INDEX!$F$2*'[2]Pillar-4'!$L$2 -> 0.04 | H21: 1 | I21: =G21*H21/SUMPRODUCT($G$4:$G$31,$H$4:$H$31) -> 0.038544929 | J21: 1 | K21: =G21*J21/SUMPRODUCT($G$4:$G$31,$J$4:$J$31) -> 0.039070131
A22: PILLAR 4 – Carbon market maturity | D22: P4 I3 – VCM retirement activity | F22: C12C | G22: =[2]INDEX!$F$2*'[2]Pillar-4'!$M$2 -> 0.03 | H22: 1 | I22: =G22*H22/SUMPRODUCT($G$4:$G$31,$H$4:$H$31) -> 0.028908697 | J22: 1.05 | K22: =G22*J22/SUMPRODUCT($G$4:$G$31,$J$4:$J$31) -> 0.030767728
A23: PILLAR 4 – Carbon market maturity | D23: P4 I4 – Article 6 institutional readiness score (0–100) | F23: C11A | G23: =[2]INDEX!$F$2*'[2]Pillar-4'!$N$2 -> 0.04 | H23: 1.1 | I23: =G23*H23/SUMPRODUCT($G$4:$G$31,$H$4:$H$31) -> 0.042399422 | J23: 1.1 | K23: =G23*J23/SUMPRODUCT($G$4:$G$31,$J$4:$J$31) -> 0.042977144
A24: PILLAR 4 – Carbon market maturity | D24: P4 I5 – Article 6 operational maturity score (0–100) | F24: C11B | G24: =[2]INDEX!$F$2*'[2]Pillar-4'!$O$2 -> 0.05 | H24: 1.1 | I24: =G24*H24/SUMPRODUCT($G$4:$G$31,$H$4:$H$31) -> 0.052999277 | J24: 1 | K24: =G24*J24/SUMPRODUCT($G$4:$G$31,$J$4:$J$31) -> 0.048837664
A25: PILLAR 5 – Macro-financial conditions | D25: P5 I1 – Domestic financial depth | F25: C16 | G25: =[2]INDEX!$G$2*'[2]Pillar-5'!$I$2 -> 0.045 | H25: 1.1 | I25: =G25*H25/SUMPRODUCT($G$4:$G$31,$H$4:$H$31) -> 0.04769935 | J25: 1 | K25: =G25*J25/SUMPRODUCT($G$4:$G$31,$J$4:$J$31) -> 0.043953897
A26: PILLAR 5 – Macro-financial conditions | D26: P5 I2 – Macroeconomic price stability | F26: C14A | G26: =[2]INDEX!$G$2*'[2]Pillar-5'!$J$2 -> 0.0375 | H26: 1 | I26: =G26*H26/SUMPRODUCT($G$4:$G$31,$H$4:$H$31) -> 0.036135871 | J26: 1 | K26: =G26*J26/SUMPRODUCT($G$4:$G$31,$J$4:$J$31) -> 0.036628248
A27: PILLAR 5 – Macro-financial conditions | D27: P5 I3 – Sovereign debt pressure | F27: C14B | G27: =[2]INDEX!$G$2*'[2]Pillar-5'!$K$2 -> 0.03 | H27: 1.05 | I27: =G27*H27/SUMPRODUCT($G$4:$G$31,$H$4:$H$31) -> 0.030354132 | J27: 1 | K27: =G27*J27/SUMPRODUCT($G$4:$G$31,$J$4:$J$31) -> 0.029302598
A28: PILLAR 5 – Macro-financial conditions | D28: P5 I4 – Exchange-rate instability | F28: C15 | G28: =[2]INDEX!$G$2*'[2]Pillar-5'!$L$2 -> 0.0375 | H28: 1 | I28: =G28*H28/SUMPRODUCT($G$4:$G$31,$H$4:$H$31) -> 0.036135871 | J28: 1 | K28: =G28*J28/SUMPRODUCT($G$4:$G$31,$J$4:$J$31) -> 0.036628248
A29: PILLAR 6 – Just transition and social credibility | D29: P6 I1 – Labour rights and social dialogue environment | F29: C18 | G29: =[2]INDEX!$H$2*'[2]Pillar-6'!$I$2 -> 0.035 | H29: 1 | I29: =G29*H29/SUMPRODUCT($G$4:$G$31,$H$4:$H$31) -> 0.033726813 | J29: 1 | K29: =G29*J29/SUMPRODUCT($G$4:$G$31,$J$4:$J$31) -> 0.034186365
A30: PILLAR 6 – Just transition and social credibility | D30: P6 I2 – Social protection and human-development resilience | F30: C19 | G30: =[2]INDEX!$H$2*'[2]Pillar-6'!$K$2 -> 0.045 | H30: 1.1 | I30: =G30*H30/SUMPRODUCT($G$4:$G$31,$H$4:$H$31) -> 0.04769935 | J30: 1.05 | K30: =G30*J30/SUMPRODUCT($G$4:$G$31,$J$4:$J$31) -> 0.046151592
A31: PILLAR 6 – Just transition and social credibility | D31: P6 I3 – Labour-market absorption risk | F31: C20 | G31: =[2]INDEX!$H$2*'[2]Pillar-6'!$L$2 -> 0.02 | H31: 1.05 | I31: =G31*H31/SUMPRODUCT($G$4:$G$31,$H$4:$H$31) -> 0.020236088 | J31: 1 | K31: =G31*J31/SUMPRODUCT($G$4:$G$31,$J$4:$J$31) -> 0.019535065
E32: Weight totals | G32: =SUM(G4:G31) -> 1 | I32: =SUM(I4:I31) -> 1 | K32: =SUM(K4:K31) -> 1
A35: Country | B35: ISO3 | C35: Base score | D35: Base rank | E35: Q1 overlay score | F35: Q1 rank | G35: Q1 score change | H35: Q1 rank change | I35: Q2 overlay score | J35: Q2 rank | K35: Q2 rank change
A36: Australia | B36: AUS | C36: =_xlfn.XLOOKUP($B36,[3]INDEX!$B$4:$B$39,[3]INDEX!$I$4:$I$39,"") -> 63.028005 | D36: =_xlfn.XLOOKUP($B36,[3]INDEX!$B$4:$B$39,[3]INDEX!$J$4:$J$39,"") -> 6 | E36: =IFERROR(_xlfn.LET(_xlpm.iso,$B36,_xlpm.s,_xlfn.VSTACK(_xlfn.XLOOKUP(_xlpm.iso,'[3]Pillar-1'!$B$5:$B$40,'[3]Pillar-1'!$J$5:$J$40),_xlfn.XLOOKUP(_xlpm.iso,'[3]Pillar-1'!$B$5:$B$40,'[3]Pillar-1'!$K$5:$K$40),_xlfn.XLOOKUP(_xlpm.iso,'[3]Pillar-1'!$B$5:$B$40,'[3]Pillar-1'!$L$5:$L$40),_xlfn.XLOOKUP(_xlpm.iso,'[3]Pillar-2'!$B$5:$B$40,'[3]Pillar-2'!$K$5:$K$40),_xlfn.XLOOKUP(_xlpm.iso,'[3]Pillar-2'!$B$5:$B$40,'[3]Pillar-2'!$L$5:$L$40),_xlfn.XLOOKUP(_xlpm.iso,'[3]Pillar-2'!$B$5:$B$40,'[3]Pillar-2'!$M$5:$M$40),_xlfn.XLOOKUP(_xlpm.iso,'[3]Pillar-2'!$B$5:$B$40,'[3]Pillar-2'!$N$5:$N$40),_xlfn.XLOOKUP(_xlpm.iso,'[3]Pillar-2'!$B$5:$B$40,'[3]Pillar-2'!$O$5:$O$40),_xlfn.XLOOKUP(_xlpm.iso,'[3]Pillar-2'!$B$5:$B$40,'[3]Pillar-2'!$P$5:$P$40),_xlfn.XLOOKUP(_xlpm.iso,'[3]Pillar-2'!$B$5:$B$40,'[3]Pillar-2'!$Q$5:$Q$40),_xlfn.XLOOKUP(_xlpm.iso,'[3]Pillar-2'!$B$5:$B$40,'[3]Pillar-2'!$R$5:$R$40),_xlfn.XLOOKUP(_xlpm.iso,'[3]Pillar-3'!$B$5:$B$40,'[3]Pillar-3'!$H$5:$H$40),_xlfn.XLOOKUP(_xlpm.iso,'[3]Pillar-3'!$B$5:$B$40,'[3]Pillar-3'!$I$5:$I$40),_xlfn.XLOOKUP(_xlpm.iso,'[3]Pillar-3'!$B$5:$B$40,'[3]Pillar-3'!$J$5:$J$40),_xlfn.XLOOKUP(_xlpm.iso,'[3]Pillar-3'!$B$5:$B$40,'[3]Pillar-3'!$K$5:$K$40),_xlfn.XLOOKUP(_xlpm.iso,'[3]Pillar-3'!$B$5:$B$40,'[3]Pillar-3'!$L$5:$L$40),_xlfn.XLOOKUP(_xlpm.iso,'[3]Pillar-4'!$B$5:$B$40,'[3]Pillar-4'!$K$5:$K$40),_xlfn.XLOOKUP(_xlpm.iso,'[3]Pillar-4'!$B$5:$B$40,'[3]Pillar-4'!$L$5:$L$40),_xlfn.XLOOKUP(_xlpm.iso,'[3]Pillar-4'!$B$5:$B$40,'[3]Pillar-4'!$M$5:$M$40),_xlfn.XLOOKUP(_xlpm.iso,'[3]Pillar-4'!$B$5:$B$40,'[3]Pillar-4'!$N$5:$N$40),_xlfn.XLOOKUP(_xlpm.iso,'[3]Pillar-4'!$B$5:$B$40,'[3]Pillar-4'!$O$5:$O$40),_xlfn.XLOOKUP(_xlpm.iso,'[3]Pillar-5'!$B$5:$B$40,'[3]Pillar-5'!$I$5:$I$40),_xlfn.XLOOKUP(_xlpm.iso,'[3]Pillar-5'!$B$5:$B$40,'[3]Pillar-5'!$J$5:$J$40),_xlfn.XLOOKUP(_xlpm.iso,'[3]Pillar-5'!$B$5:$B$40,'[3]Pillar-5'!$K$5:$K$40),_xlfn.XLOOKUP(_xlpm.iso,'[3]Pillar-5'!$B$5:$B$40,'[3]Pillar-5'!$L$5:$L$40),_xlfn.XLOOKUP(_xlpm.iso,'[3]Pillar-6'!$B$5:$B$40,'[3]Pillar-6'!$I$5:$I$40),_xlfn.XLOOKUP(_xlpm.iso,'[3]Pillar-6'!$B$5:$B$40,'[3]Pillar-6'!$K$5:$K$40),_xlfn.XLOOKUP(_xlpm.iso,'[3]Pillar-6'!$B$5:$B$40,'[3]Pillar-6'!$L$5:$L$40)),SUMPRODUCT(_xlpm.s,$I$4:$I$31)),"") -> 62.473414 | F36: =IF(E36="","",_xlfn.RANK.EQ(E36,$E$36:$E$71,0)) -> 7 | G36: =IF(E36="","",E36-C36) -> -0.55459152 | H36: =IF(F36="","",D36-F36) -> -1 | I36: =IFERROR(_xlfn.LET(_xlpm.iso,$B36,_xlpm.s,_xlfn.VSTACK(_xlfn.XLOOKUP(_xlpm.iso,'[3]Pillar-1'!$B$5:$B$40,'[3]Pillar-1'!$J$5:$J$40),_xlfn.XLOOKUP(_xlpm.iso,'[3]Pillar-1'!$B$5:$B$40,'[3]Pillar-1'!$K$5:$K$40),_xlfn.XLOOKUP(_xlpm.iso,'[3]Pillar-1'!$B$5:$B$40,'[3]Pillar-1'!$L$5:$L$40),_xlfn.XLOOKUP(_xlpm.iso,'[3]Pillar-2'!$B$5:$B$40,'[3]Pillar-2'!$K$5:$K$40),_xlfn.XLOOKUP(_xlpm.iso,'[3]Pillar-2'!$B$5:$B$40,'[3]Pillar-2'!$L$5:$L$40),_xlfn.XLOOKUP(_xlpm.iso,'[3]Pillar-2'!$B$5:$B$40,'[3]Pillar-2'!$M$5:$M$40),_xlfn.XLOOKUP(_xlpm.iso,'[3]Pillar-2'!$B$5:$B$40,'[3]Pillar-2'!$N$5:$N$40),_xlfn.XLOOKUP(_xlpm.iso,'[3]Pillar-2'!$B$5:$B$40,'[3]Pillar-2'!$O$5:$O$40),_xlfn.XLOOKUP(_xlpm.iso,'[3]Pillar-2'!$B$5:$B$40,'[3]Pillar-2'!$P$5:$P$40),_xlfn.XLOOKUP(_xlpm.iso,'[3]Pillar-2'!$B$5:$B$40,'[3]Pillar-2'!$Q$5:$Q$40),_xlfn.XLOOKUP(_xlpm.iso,'[3]Pillar-2'!$B$5:$B$40,'[3]Pillar-2'!$R$5:$R$40),_xlfn.XLOOKUP(_xlpm.iso,'[3]Pillar-3'!$B$5:$B$40,'[3]Pillar-3'!$H$5:$H$40),_xlfn.XLOOKUP(_xlpm.iso,'[3]Pillar-3'!$B$5:$B$40,'[3]Pillar-3'!$I$5:$I$40),_xlfn.XLOOKUP(_xlpm.iso,'[3]Pillar-3'!$B$5:$B$40,'[3]Pillar-3'!$J$5:$J$40),_xlfn.XLOOKUP(_xlpm.iso,'[3]Pillar-3'!$B$5:$B$40,'[3]Pillar-3'!$K$5:$K$40),_xlfn.XLOOKUP(_xlpm.iso,'[3]Pillar-3'!$B$5:$B$40,'[3]Pillar-3'!$L$5:$L$40),_xlfn.XLOOKUP(_xlpm.iso,'[3]Pillar-4'!$B$5:$B$40,'[3]Pillar-4'!$K$5:$K$40),_xlfn.XLOOKUP(_xlpm.iso,'[3]Pillar-4'!$B$5:$B$40,'[3]Pillar-4'!$L$5:$L$40),_xlfn.XLOOKUP(_xlpm.iso,'[3]Pillar-4'!$B$5:$B$40,'[3]Pillar-4'!$M$5:$M$40),_xlfn.XLOOKUP(_xlpm.iso,'[3]Pillar-4'!$B$5:$B$40,'[3]Pillar-4'!$N$5:$N$40),_xlfn.XLOOKUP(_xlpm.iso,'[3]Pillar-4'!$B$5:$B$40,'[3]Pillar-4'!$O$5:$O$40),_xlfn.XLOOKUP(_xlpm.iso,'[3]Pillar-5'!$B$5:$B$40,'[3]Pillar-5'!$I$5:$I$40),_xlfn.XLOOKUP(_xlpm.iso,'[3]Pillar-5'!$B$5:$B$40,'[3]Pillar-5'!$J$5:$J$40),_xlfn.XLOOKUP(_xlpm.iso,'[3]Pillar-5'!$B$5:$B$40,'[3]Pillar-5'!$K$5:$K$40),_xlfn.XLOOKUP(_xlpm.iso,'[3]Pillar-5'!$B$5:$B$40,'[3]Pillar-5'!$L$5:$L$40),_xlfn.XLOOKUP(_xlpm.iso,'[3]Pillar-6'!$B$5:$B$40,'[3]Pillar-6'!$I$5:$I$40),_xlfn.XLOOKUP(_xlpm.iso,'[3]Pillar-6'!$B$5:$B$40,'[3]Pillar-6'!$K$5:$K$40),_xlfn.XLOOKUP(_xlpm.iso,'[3]Pillar-6'!$B$5:$B$40,'[3]Pillar-6'!$L$5:$L$40)),SUMPRODUCT(_xlpm.s,$K$4:$K$31)),"") -> 62.558096 | J36: =IF(I36="","",_xlfn.RANK.EQ(I36,$I$36:$I$71,0)) -> 7 | K36: =IF(J36="","",D36-J36) -> -1
A37: Bangladesh | B37: BGD | C37: =_xlfn.XLOOKUP($B37,[3]INDEX!$B$4:$B$39,[3]INDEX!$I$4:$I$39,"") -> 35.835974 | D37: =_xlfn.XLOOKUP($B37,[3]INDEX!$B$4:$B$39,[3]INDEX!$J$4:$J$39,"") -> 36 | E37: =IFERROR(_xlfn.LET(_xlpm.iso,$B37,_xlpm.s,_xlfn.VSTACK(_xlfn.XLOOKUP(_xlpm.iso,'[3]Pillar-1'!$B$5:$B$40,'[3]Pillar-1'!$J$5:$J$40),_xlfn.XLOOKUP(_xlpm.iso,'[3]Pillar-1'!$B$5:$B$40,'[3]Pillar-1'!$K$5:$K$40),_xlfn.XLOOKUP(_xlpm.iso,'[3]Pillar-1'!$B$5:$B$40,'[3]Pillar-1'!$L$5:$L$40),_xlfn.XLOOKUP(_xlpm.iso,'[3]Pillar-2'!$B$5:$B$40,'[3]Pillar-2'!$K$5:$K$40),_xlfn.XLOOKUP(_xlpm.iso,'[3]Pillar-2'!$B$5:$B$40,'[3]Pillar-2'!$L$5:$L$40),_xlfn.XLOOKUP(_xlpm.iso,'[3]Pillar-2'!$B$5:$B$40,'[3]Pillar-2'!$M$5:$M$40),_xlfn.XLOOKUP(_xlpm.iso,'[3]Pillar-2'!$B$5:$B$40,'[3]Pillar-2'!$N$5:$N$40),_xlfn.XLOOKUP(_xlpm.iso,'[3]Pillar-2'!$B$5:$B$40,'[3]Pillar-2'!$O$5:$O$40),_xlfn.XLOOKUP(_xlpm.iso,'[3]Pillar-2'!$B$5:$B$40,'[3]Pillar-2'!$P$5:$P$40),_xlfn.XLOOKUP(_xlpm.iso,'[3]Pillar-2'!$B$5:$B$40,'[3]Pillar-2'!$Q$5:$Q$40),_xlfn.XLOOKUP(_xlpm.iso,'[3]Pillar-2'!$B$5:$B$40,'[3]Pillar-2'!$R$5:$R$40),_xlfn.XLOOKUP(_xlpm.iso,'[3]Pillar-3'!$B$5:$B$40,'[3]Pillar-3'!$H$5:$H$40),_xlfn.XLOOKUP(_xlpm.iso,'[3]Pillar-3'!$B$5:$B$40,'[3]Pillar-3'!$I$5:$I$40),_xlfn.XLOOKUP(_xlpm.iso,'[3]Pillar-3'!$B$5:$B$40,'[3]Pillar-3'!$J$5:$J$40),_xlfn.XLOOKUP(_xlpm.iso,'[3]Pillar-3'!$B$5:$B$40,'[3]Pillar-3'!$K$5:$K$40),_xlfn.XLOOKUP(_xlpm.iso,'[3]Pillar-3'!$B$5:$B$40,'[3]Pillar-3'!$L$5:$L$40),_xlfn.XLOOKUP(_xlpm.iso,'[3]Pillar-4'!$B$5:$B$40,'[3]Pillar-4'!$K$5:$K$40),_xlfn.XLOOKUP(_xlpm.iso,'[3]Pillar-4'!$B$5:$B$40,'[3]Pillar-4'!$L$5:$L$40),_xlfn.XLOOKUP(_xlpm.iso,'[3]Pillar-4'!$B$5:$B$40,'[3]Pillar-4'!$M$5:$M$40),_xlfn.XLOOKUP(_xlpm.iso,'[3]Pillar-4'!$B$5:$B$40,'[3]Pillar-4'!$N$5:$N$40),_xlfn.XLOOKUP(_xlpm.iso,'[3]Pillar-4'!$B$5:$B$40,'[3]Pillar-4'!$O$5:$O$40),_xlfn.XLOOKUP(_xlpm.iso,'[3]Pillar-5'!$B$5:$B$40,'[3]Pillar-5'!$I$5:$I$40),_xlfn.XLOOKUP(_xlpm.iso,'[3]Pillar-5'!$B$5:$B$40,'[3]Pillar-5'!$J$5:$J$40),_xlfn.XLOOKUP(_xlpm.iso,'[3]Pillar-5'!$B$5:$B$40,'[3]Pillar-5'!$K$5:$K$40),_xlfn.XLOOKUP(_xlpm.iso,'[3]Pillar-5'!$B$5:$B$40,'[3]Pillar-5'!$L$5:$L$40),_xlfn.XLOOKUP(_xlpm.iso,'[3]Pillar-6'!$B$5:$B$40,'[3]Pillar-6'!$I$5:$I$40),_xlfn.XLOOKUP(_xlpm.iso,'[3]Pillar-6'!$B$5:$B$40,'[3]Pillar-6'!$K$5:$K$40),_xlfn.XLOOKUP(_xlpm.iso,'[3]Pillar-6'!$B$5:$B$40,'[3]Pillar-6'!$L$5:$L$40)),SUMPRODUCT(_xlpm.s,$I$4:$I$31)),"") -> 35.910616 | F37: =IF(E37="","",_xlfn.RANK.EQ(E37,$E$36:$E$71,0)) -> 35 | G37: =IF(E37="","",E37-C37) -> 0.074641857 | H37: =IF(F37="","",D37-F37) -> 1 | I37: =IFERROR(_xlfn.LET(_xlpm.iso,$B37,_xlpm.s,_xlfn.VSTACK(_xlfn.XLOOKUP(_xlpm.iso,'[3]Pillar-1'!$B$5:$B$40,'[3]Pillar-1'!$J$5:$J$40),_xlfn.XLOOKUP(_xlpm.iso,'[3]Pillar-1'!$B$5:$B$40,'[3]Pillar-1'!$K$5:$K$40),_xlfn.XLOOKUP(_xlpm.iso,'[3]Pillar-1'!$B$5:$B$40,'[3]Pillar-1'!$L$5:$L$40),_xlfn.XLOOKUP(_xlpm.iso,'[3]Pillar-2'!$B$5:$B$40,'[3]Pillar-2'!$K$5:$K$40),_xlfn.XLOOKUP(_xlpm.iso,'[3]Pillar-2'!$B$5:$B$40,'[3]Pillar-2'!$L$5:$L$40),_xlfn.XLOOKUP(_xlpm.iso,'[3]Pillar-2'!$B$5:$B$40,'[3]Pillar-2'!$M$5:$M$40),_xlfn.XLOOKUP(_xlpm.iso,'[3]Pillar-2'!$B$5:$B$40,'[3]Pillar-2'!$N$5:$N$40),_xlfn.XLOOKUP(_xlpm.iso,'[3]Pillar-2'!$B$5:$B$40,'[3]Pillar-2'!$O$5:$O$40),_xlfn.XLOOKUP(_xlpm.iso,'[3]Pillar-2'!$B$5:$B$40,'[3]Pillar-2'!$P$5:$P$40),_xlfn.XLOOKUP(_xlpm.iso,'[3]Pillar-2'!$B$5:$B$40,'[3]Pillar-2'!$Q$5:$Q$40),_xlfn.XLOOKUP(_xlpm.iso,'[3]Pillar-2'!$B$5:$B$40,'[3]Pillar-2'!$R$5:$R$40),_xlfn.XLOOKUP(_xlpm.iso,'[3]Pillar-3'!$B$5:$B$40,'[3]Pillar-3'!$H$5:$H$40),_xlfn.XLOOKUP(_xlpm.iso,'[3]Pillar-3'!$B$5:$B$40,'[3]Pillar-3'!$I$5:$I$40),_xlfn.XLOOKUP(_xlpm.iso,'[3]Pillar-3'!$B$5:$B$40,'[3]Pillar-3'!$J$5:$J$40),_xlfn.XLOOKUP(_xlpm.iso,'[3]Pillar-3'!$B$5:$B$40,'[3]Pillar-3'!$K$5:$K$40),_xlfn.XLOOKUP(_xlpm.iso,'[3]Pillar-3'!$B$5:$B$40,'[3]Pillar-3'!$L$5:$L$40),_xlfn.XLOOKUP(_xlpm.iso,'[3]Pillar-4'!$B$5:$B$40,'[3]Pillar-4'!$K$5:$K$40),_xlfn.XLOOKUP(_xlpm.iso,'[3]Pillar-4'!$B$5:$B$40,'[3]Pillar-4'!$L$5:$L$40),_xlfn.XLOOKUP(_xlpm.iso,'[3]Pillar-4'!$B$5:$B$40,'[3]Pillar-4'!$M$5:$M$40),_xlfn.XLOOKUP(_xlpm.iso,'[3]Pillar-4'!$B$5:$B$40,'[3]Pillar-4'!$N$5:$N$40),_xlfn.XLOOKUP(_xlpm.iso,'[3]Pillar-4'!$B$5:$B$40,'[3]Pillar-4'!$O$5:$O$40),_xlfn.XLOOKUP(_xlpm.iso,'[3]Pillar-5'!$B$5:$B$40,'[3]Pillar-5'!$I$5:$I$40),_xlfn.XLOOKUP(_xlpm.iso,'[3]Pillar-5'!$B$5:$B$40,'[3]Pillar-5'!$J$5:$J$40),_xlfn.XLOOKUP(_xlpm.iso,'[3]Pillar-5'!$B$5:$B$40,'[3]Pillar-5'!$K$5:$K$40),_xlfn.XLOOKUP(_xlpm.iso,'[3]Pillar-5'!$B$5:$B$40,'[3]Pillar-5'!$L$5:$L$40),_xlfn.XLOOKUP(_xlpm.iso,'[3]Pillar-6'!$B$5:$B$40,'[3]Pillar-6'!$I$5:$I$40),_xlfn.XLOOKUP(_xlpm.iso,'[3]Pillar-6'!$B$5:$B$40,'[3]Pillar-6'!$K$5:$K$40),_xlfn.XLOOKUP(_xlpm.iso,'[3]Pillar-6'!$B$5:$B$40,'[3]Pillar-6'!$L$5:$L$40)),SUMPRODUCT(_xlpm.s,$K$4:$K$31)),"") -> 35.804635 | J37: =IF(I37="","",_xlfn.RANK.EQ(I37,$I$36:$I$71,0)) -> 36 | K37: =IF(J37="","",D37-J37) -> 0
A38: Bosnia and Herzegovina | B38: BIH | C38: =_xlfn.XLOOKUP($B38,[3]INDEX!$B$4:$B$39,[3]INDEX!$I$4:$I$39,"") -> 36.142382 | D38: =_xlfn.XLOOKUP($B38,[3]INDEX!$B$4:$B$39,[3]INDEX!$J$4:$J$39,"") -> 35 | E38: =IFERROR(_xlfn.LET(_xlpm.iso,$B38,_xlpm.s,_xlfn.VSTACK(_xlfn.XLOOKUP(_xlpm.iso,'[3]Pillar-1'!$B$5:$B$40,'[3]Pillar-1'!$J$5:$J$40),_xlfn.XLOOKUP(_xlpm.iso,'[3]Pillar-1'!$B$5:$B$40,'[3]Pillar-1'!$K$5:$K$40),_xlfn.XLOOKUP(_xlpm.iso,'[3]Pillar-1'!$B$5:$B$40,'[3]Pillar-1'!$L$5:$L$40),_xlfn.XLOOKUP(_xlpm.iso,'[3]Pillar-2'!$B$5:$B$40,'[3]Pillar-2'!$K$5:$K$40),_xlfn.XLOOKUP(_xlpm.iso,'[3]Pillar-2'!$B$5:$B$40,'[3]Pillar-2'!$L$5:$L$40),_xlfn.XLOOKUP(_xlpm.iso,'[3]Pillar-2'!$B$5:$B$40,'[3]Pillar-2'!$M$5:$M$40),_xlfn.XLOOKUP(_xlpm.iso,'[3]Pillar-2'!$B$5:$B$40,'[3]Pillar-2'!$N$5:$N$40),_xlfn.XLOOKUP(_xlpm.iso,'[3]Pillar-2'!$B$5:$B$40,'[3]Pillar-2'!$O$5:$O$40),_xlfn.XLOOKUP(_xlpm.iso,'[3]Pillar-2'!$B$5:$B$40,'[3]Pillar-2'!$P$5:$P$40),_xlfn.XLOOKUP(_xlpm.iso,'[3]Pillar-2'!$B$5:$B$40,'[3]Pillar-2'!$Q$5:$Q$40),_xlfn.XLOOKUP(_xlpm.iso,'[3]Pillar-2'!$B$5:$B$40,'[3]Pillar-2'!$R$5:$R$40),_xlfn.XLOOKUP(_xlpm.iso,'[3]Pillar-3'!$B$5:$B$40,'[3]Pillar-3'!$H$5:$H$40),_xlfn.XLOOKUP(_xlpm.iso,'[3]Pillar-3'!$B$5:$B$40,'[3]Pillar-3'!$I$5:$I$40),_xlfn.XLOOKUP(_xlpm.iso,'[3]Pillar-3'!$B$5:$B$40,'[3]Pillar-3'!$J$5:$J$40),_xlfn.XLOOKUP(_xlpm.iso,'[3]Pillar-3'!$B$5:$B$40,'[3]Pillar-3'!$K$5:$K$40),_xlfn.XLOOKUP(_xlpm.iso,'[3]Pillar-3'!$B$5:$B$40,'[3]Pillar-3'!$L$5:$L$40),_xlfn.XLOOKUP(_xlpm.iso,'[3]Pillar-4'!$B$5:$B$40,'[3]Pillar-4'!$K$5:$K$40),_xlfn.XLOOKUP(_xlpm.iso,'[3]Pillar-4'!$B$5:$B$40,'[3]Pillar-4'!$L$5:$L$40),_xlfn.XLOOKUP(_xlpm.iso,'[3]Pillar-4'!$B$5:$B$40,'[3]Pillar-4'!$M$5:$M$40),_xlfn.XLOOKUP(_xlpm.iso,'[3]Pillar-4'!$B$5:$B$40,'[3]Pillar-4'!$N$5:$N$40),_xlfn.XLOOKUP(_xlpm.iso,'[3]Pillar-4'!$B$5:$B$40,'[3]Pillar-4'!$O$5:$O$40),_xlfn.XLOOKUP(_xlpm.iso,'[3]Pillar-5'!$B$5:$B$40,'[3]Pillar-5'!$I$5:$I$40),_xlfn.XLOOKUP(_xlpm.iso,'[3]Pillar-5'!$B$5:$B$40,'[3]Pillar-5'!$J$5:$J$40),_xlfn.XLOOKUP(_xlpm.iso,'[3]Pillar-5'!$B$5:$B$40,'[3]Pillar-5'!$K$5:$K$40),_xlfn.XLOOKUP(_xlpm.iso,'[3]Pillar-5'!$B$5:$B$40,'[3]Pillar-5'!$L$5:$L$40),_xlfn.XLOOKUP(_xlpm.iso,'[3]Pillar-6'!$B$5:$B$40,'[3]Pillar-6'!$I$5:$I$40),_xlfn.XLOOKUP(_xlpm.iso,'[3]Pillar-6'!$B$5:$B$40,'[3]Pillar-6'!$K$5:$K$40),_xlfn.XLOOKUP(_xlpm.iso,'[3]Pillar-6'!$B$5:$B$40,'[3]Pillar-6'!$L$5:$L$40)),SUMPRODUCT(_xlpm.s,$I$4:$I$31)),"") -> 35.689199 | F38: =IF(E38="","",_xlfn.RANK.EQ(E38,$E$36:$E$71,0)) -> 36 | G38: =IF(E38="","",E38-C38) -> -0.45318365 | H38: =IF(F38="","",D38-F38) -> -1 | I38: =IFERROR(_xlfn.LET(_xlpm.iso,$B38,_xlpm.s,_xlfn.VSTACK(_xlfn.XLOOKUP(_xlpm.iso,'[3]Pillar-1'!$B$5:$B$40,'[3]Pillar-1'!$J$5:$J$40),_xlfn.XLOOKUP(_xlpm.iso,'[3]Pillar-1'!$B$5:$B$40,'[3]Pillar-1'!$K$5:$K$40),_xlfn.XLOOKUP(_xlpm.iso,'[3]Pillar-1'!$B$5:$B$40,'[3]Pillar-1'!$L$5:$L$40),_xlfn.XLOOKUP(_xlpm.iso,'[3]Pillar-2'!$B$5:$B$40,'[3]Pillar-2'!$K$5:$K$40),_xlfn.XLOOKUP(_xlpm.iso,'[3]Pillar-2'!$B$5:$B$40,'[3]Pillar-2'!$L$5:$L$40),_xlfn.XLOOKUP(_xlpm.iso,'[3]Pillar-2'!$B$5:$B$40,'[3]Pillar-2'!$M$5:$M$40),_xlfn.XLOOKUP(_xlpm.iso,'[3]Pillar-2'!$B$5:$B$40,'[3]Pillar-2'!$N$5:$N$40),_xlfn.XLOOKUP(_xlpm.iso,'[3]Pillar-2'!$B$5:$B$40,'[3]Pillar-2'!$O$5:$O$40),_xlfn.XLOOKUP(_xlpm.iso,'[3]Pillar-2'!$B$5:$B$40,'[3]Pillar-2'!$P$5:$P$40),_xlfn.XLOOKUP(_xlpm.iso,'[3]Pillar-2'!$B$5:$B$40,'[3]Pillar-2'!$Q$5:$Q$40),_xlfn.XLOOKUP(_xlpm.iso,'[3]Pillar-2'!$B$5:$B$40,'[3]Pillar-2'!$R$5:$R$40),_xlfn.XLOOKUP(_xlpm.iso,'[3]Pillar-3'!$B$5:$B$40,'[3]Pillar-3'!$H$5:$H$40),_xlfn.XLOOKUP(_xlpm.iso,'[3]Pillar-3'!$B$5:$B$40,'[3]Pillar-3'!$I$5:$I$40),_xlfn.XLOOKUP(_xlpm.iso,'[3]Pillar-3'!$B$5:$B$40,'[3]Pillar-3'!$J$5:$J$40),_xlfn.XLOOKUP(_xlpm.iso,'[3]Pillar-3'!$B$5:$B$40,'[3]Pillar-3'!$K$5:$K$40),_xlfn.XLOOKUP(_xlpm.iso,'[3]Pillar-3'!$B$5:$B$40,'[3]Pillar-3'!$L$5:$L$40),_xlfn.XLOOKUP(_xlpm.iso,'[3]Pillar-4'!$B$5:$B$40,'[3]Pillar-4'!$K$5:$K$40),_xlfn.XLOOKUP(_xlpm.iso,'[3]Pillar-4'!$B$5:$B$40,'[3]Pillar-4'!$L$5:$L$40),_xlfn.XLOOKUP(_xlpm.iso,'[3]Pillar-4'!$B$5:$B$40,'[3]Pillar-4'!$M$5:$M$40),_xlfn.XLOOKUP(_xlpm.iso,'[3]Pillar-4'!$B$5:$B$40,'[3]Pillar-4'!$N$5:$N$40),_xlfn.XLOOKUP(_xlpm.iso,'[3]Pillar-4'!$B$5:$B$40,'[3]Pillar-4'!$O$5:$O$40),_xlfn.XLOOKUP(_xlpm.iso,'[3]Pillar-5'!$B$5:$B$40,'[3]Pillar-5'!$I$5:$I$40),_xlfn.XLOOKUP(_xlpm.iso,'[3]Pillar-5'!$B$5:$B$40,'[3]Pillar-5'!$J$5:$J$40),_xlfn.XLOOKUP(_xlpm.iso,'[3]Pillar-5'!$B$5:$B$40,'[3]Pillar-5'!$K$5:$K$40),_xlfn.XLOOKUP(_xlpm.iso,'[3]Pillar-5'!$B$5:$B$40,'[3]Pillar-5'!$L$5:$L$40),_xlfn.XLOOKUP(_xlpm.iso,'[3]Pillar-6'!$B$5:$B$40,'[3]Pillar-6'!$I$5:$I$40),_xlfn.XLOOKUP(_xlpm.iso,'[3]Pillar-6'!$B$5:$B$40,'[3]Pillar-6'!$K$5:$K$40),_xlfn.XLOOKUP(_xlpm.iso,'[3]Pillar-6'!$B$5:$B$40,'[3]Pillar-6'!$L$5:$L$40)),SUMPRODUCT(_xlpm.s,$K$4:$K$31)),"") -> 35.854068 | J38: =IF(I38="","",_xlfn.RANK.EQ(I38,$I$36:$I$71,0)) -> 35 | K38: =IF(J38="","",D38-J38) -> 0
A39: Brazil | B39: BRA | C39: =_xlfn.XLOOKUP($B39,[3]INDEX!$B$4:$B$39,[3]INDEX!$I$4:$I$39,"") -> 64.650458 | D39: =_xlfn.XLOOKUP($B39,[3]INDEX!$B$4:$B$39,[3]INDEX!$J$4:$J$39,"") -> 5 | E39: =IFERROR(_xlfn.LET(_xlpm.iso,$B39,_xlpm.s,_xlfn.VSTACK(_xlfn.XLOOKUP(_xlpm.iso,'[3]Pillar-1'!$B$5:$B$40,'[3]Pillar-1'!$J$5:$J$40),_xlfn.XLOOKUP(_xlpm.iso,'[3]Pillar-1'!$B$5:$B$40,'[3]Pillar-1'!$K$5:$K$40),_xlfn.XLOOKUP(_xlpm.iso,'[3]Pillar-1'!$B$5:$B$40,'[3]Pillar-1'!$L$5:$L$40),_xlfn.XLOOKUP(_xlpm.iso,'[3]Pillar-2'!$B$5:$B$40,'[3]Pillar-2'!$K$5:$K$40),_xlfn.XLOOKUP(_xlpm.iso,'[3]Pillar-2'!$B$5:$B$40,'[3]Pillar-2'!$L$5:$L$40),_xlfn.XLOOKUP(_xlpm.iso,'[3]Pillar-2'!$B$5:$B$40,'[3]Pillar-2'!$M$5:$M$40),_xlfn.XLOOKUP(_xlpm.iso,'[3]Pillar-2'!$B$5:$B$40,'[3]Pillar-2'!$N$5:$N$40),_xlfn.XLOOKUP(_xlpm.iso,'[3]Pillar-2'!$B$5:$B$40,'[3]Pillar-2'!$O$5:$O$40),_xlfn.XLOOKUP(_xlpm.iso,'[3]Pillar-2'!$B$5:$B$40,'[3]Pillar-2'!$P$5:$P$40),_xlfn.XLOOKUP(_xlpm.iso,'[3]Pillar-2'!$B$5:$B$40,'[3]Pillar-2'!$Q$5:$Q$40),_xlfn.XLOOKUP(_xlpm.iso,'[3]Pillar-2'!$B$5:$B$40,'[3]Pillar-2'!$R$5:$R$40),_xlfn.XLOOKUP(_xlpm.iso,'[3]Pillar-3'!$B$5:$B$40,'[3]Pillar-3'!$H$5:$H$40),_xlfn.XLOOKUP(_xlpm.iso,'[3]Pillar-3'!$B$5:$B$40,'[3]Pillar-3'!$I$5:$I$40),_xlfn.XLOOKUP(_xlpm.iso,'[3]Pillar-3'!$B$5:$B$40,'[3]Pillar-3'!$J$5:$J$40),_xlfn.XLOOKUP(_xlpm.iso,'[3]Pillar-3'!$B$5:$B$40,'[3]Pillar-3'!$K$5:$K$40),_xlfn.XLOOKUP(_xlpm.iso,'[3]Pillar-3'!$B$5:$B$40,'[3]Pillar-3'!$L$5:$L$40),_xlfn.XLOOKUP(_xlpm.iso,'[3]Pillar-4'!$B$5:$B$40,'[3]Pillar-4'!$K$5:$K$40),_xlfn.XLOOKUP(_xlpm.iso,'[3]Pillar-4'!$B$5:$B$40,'[3]Pillar-4'!$L$5:$L$40),_xlfn.XLOOKUP(_xlpm.iso,'[3]Pillar-4'!$B$5:$B$40,'[3]Pillar-4'!$M$5:$M$40),_xlfn.XLOOKUP(_xlpm.iso,'[3]Pillar-4'!$B$5:$B$40,'[3]Pillar-4'!$N$5:$N$40),_xlfn.XLOOKUP(_xlpm.iso,'[3]Pillar-4'!$B$5:$B$40,'[3]Pillar-4'!$O$5:$O$40),_xlfn.XLOOKUP(_xlpm.iso,'[3]Pillar-5'!$B$5:$B$40,'[3]Pillar-5'!$I$5:$I$40),_xlfn.XLOOKUP(_xlpm.iso,'[3]Pillar-5'!$B$5:$B$40,'[3]Pillar-5'!$J$5:$J$40),_xlfn.XLOOKUP(_xlpm.iso,'[3]Pillar-5'!$B$5:$B$40,'[3]Pillar-5'!$K$5:$K$40),_xlfn.XLOOKUP(_xlpm.iso,'[3]Pillar-5'!$B$5:$B$40,'[3]Pillar-5'!$L$5:$L$40),_xlfn.XLOOKUP(_xlpm.iso,'[3]Pillar-6'!$B$5:$B$40,'[3]Pillar-6'!$I$5:$I$40),_xlfn.XLOOKUP(_xlpm.iso,'[3]Pillar-6'!$B$5:$B$40,'[3]Pillar-6'!$K$5:$K$40),_xlfn.XLOOKUP(_xlpm.iso,'[3]Pillar-6'!$B$5:$B$40,'[3]Pillar-6'!$L$5:$L$40)),SUMPRODUCT(_xlpm.s,$I$4:$I$31)),"") -> 63.893083 | F39: =IF(E39="","",_xlfn.RANK.EQ(E39,$E$36:$E$71,0)) -> 5 | G39: =IF(E39="","",E39-C39) -> -0.7573752 | H39: =IF(F39="","",D39-F39) -> 0 | I39: =IFERROR(_xlfn.LET(_xlpm.iso,$B39,_xlpm.s,_xlfn.VSTACK(_xlfn.XLOOKUP(_xlpm.iso,'[3]Pillar-1'!$B$5:$B$40,'[3]Pillar-1'!$J$5:$J$40),_xlfn.XLOOKUP(_xlpm.iso,'[3]Pillar-1'!$B$5:$B$40,'[3]Pillar-1'!$K$5:$K$40),_xlfn.XLOOKUP(_xlpm.iso,'[3]Pillar-1'!$B$5:$B$40,'[3]Pillar-1'!$L$5:$L$40),_xlfn.XLOOKUP(_xlpm.iso,'[3]Pillar-2'!$B$5:$B$40,'[3]Pillar-2'!$K$5:$K$40),_xlfn.XLOOKUP(_xlpm.iso,'[3]Pillar-2'!$B$5:$B$40,'[3]Pillar-2'!$L$5:$L$40),_xlfn.XLOOKUP(_xlpm.iso,'[3]Pillar-2'!$B$5:$B$40,'[3]Pillar-2'!$M$5:$M$40),_xlfn.XLOOKUP(_xlpm.iso,'[3]Pillar-2'!$B$5:$B$40,'[3]Pillar-2'!$N$5:$N$40),_xlfn.XLOOKUP(_xlpm.iso,'[3]Pillar-2'!$B$5:$B$40,'[3]Pillar-2'!$O$5:$O$40),_xlfn.XLOOKUP(_xlpm.iso,'[3]Pillar-2'!$B$5:$B$40,'[3]Pillar-2'!$P$5:$P$40),_xlfn.XLOOKUP(_xlpm.iso,'[3]Pillar-2'!$B$5:$B$40,'[3]Pillar-2'!$Q$5:$Q$40),_xlfn.XLOOKUP(_xlpm.iso,'[3]Pillar-2'!$B$5:$B$40,'[3]Pillar-2'!$R$5:$R$40),_xlfn.XLOOKUP(_xlpm.iso,'[3]Pillar-3'!$B$5:$B$40,'[3]Pillar-3'!$H$5:$H$40),_xlfn.XLOOKUP(_xlpm.iso,'[3]Pillar-3'!$B$5:$B$40,'[3]Pillar-3'!$I$5:$I$40),_xlfn.XLOOKUP(_xlpm.iso,'[3]Pillar-3'!$B$5:$B$40,'[3]Pillar-3'!$J$5:$J$40),_xlfn.XLOOKUP(_xlpm.iso,'[3]Pillar-3'!$B$5:$B$40,'[3]Pillar-3'!$K$5:$K$40),_xlfn.XLOOKUP(_xlpm.iso,'[3]Pillar-3'!$B$5:$B$40,'[3]Pillar-3'!$L$5:$L$40),_xlfn.XLOOKUP(_xlpm.iso,'[3]Pillar-4'!$B$5:$B$40,'[3]Pillar-4'!$K$5:$K$40),_xlfn.XLOOKUP(_xlpm.iso,'[3]Pillar-4'!$B$5:$B$40,'[3]Pillar-4'!$L$5:$L$40),_xlfn.XLOOKUP(_xlpm.iso,'[3]Pillar-4'!$B$5:$B$40,'[3]Pillar-4'!$M$5:$M$40),_xlfn.XLOOKUP(_xlpm.iso,'[3]Pillar-4'!$B$5:$B$40,'[3]Pillar-4'!$N$5:$N$40),_xlfn.XLOOKUP(_xlpm.iso,'[3]Pillar-4'!$B$5:$B$40,'[3]Pillar-4'!$O$5:$O$40),_xlfn.XLOOKUP(_xlpm.iso,'[3]Pillar-5'!$B$5:$B$40,'[3]Pillar-5'!$I$5:$I$40),_xlfn.XLOOKUP(_xlpm.iso,'[3]Pillar-5'!$B$5:$B$40,'[3]Pillar-5'!$J$5:$J$40),_xlfn.XLOOKUP(_xlpm.iso,'[3]Pillar-5'!$B$5:$B$40,'[3]Pillar-5'!$K$5:$K$40),_xlfn.XLOOKUP(_xlpm.iso,'[3]Pillar-5'!$B$5:$B$40,'[3]Pillar-5'!$L$5:$L$40),_xlfn.XLOOKUP(_xlpm.iso,'[3]Pillar-6'!$B$5:$B$40,'[3]Pillar-6'!$I$5:$I$40),_xlfn.XLOOKUP(_xlpm.iso,'[3]Pillar-6'!$B$5:$B$40,'[3]Pillar-6'!$K$5:$K$40),_xlfn.XLOOKUP(_xlpm.iso,'[3]Pillar-6'!$B$5:$B$40,'[3]Pillar-6'!$L$5:$L$40)),SUMPRODUCT(_xlpm.s,$K$4:$K$31)),"") -> 64.208841 | J39: =IF(I39="","",_xlfn.RANK.EQ(I39,$I$36:$I$71,0)) -> 5 | K39: =IF(J39="","",D39-J39) -> 0
